Workbook

Sheet 印刷メニュー
A1: 印刷メニュー
A2: B列に「○」を付けたシートをまとめて印刷します（マクロ導入後はボタン／Alt+F8で実行。導入前でも下の手順で手動一括印刷できます）。
A5: シート名 | B5: 印刷する（○） | C5: 用紙 | D5: 枚数目安 | E5: 内容
A6: 印刷01_日別人工 | B6: ○ | C6: A4縦 | D6: 3 | E6: 日付×工程の人工、自社／業者／合計
A7: 印刷02_累計推移 | B7: ○ | C7: A4横 | D7: 4 | E7: 工程別の累計人工と当日の作業内容
A8: 印刷03_グラフ | B8: ○ | C8: A4横 | D8: 1 | E8: 累計推移グラフ・日別人工グラフ
A9: 印刷04_集計 | B9: ○ | C9: A4横 | D9: 1 | E9: 工程別 実績と予算比較、業者別、作業員×工程
A10: 印刷05_工種別予算 | B10: ○ | C10: A4縦 | D10: 1 | E10: 工種ごとの実績と予算比較
A11: 印刷06_週別 | B11: ○ | C11: A4横 | D11: 1 | E11: 工程→工種×週の人工マトリクス
A12: 日別集計 | C12: A4横 | D12: 3 | E12: 日別＋累計を1枚幅に（A〜AG列すべて。文字は小さめ）
A13: 台帳 | C13: A4横 | D13: 6 | E13: 元データ（見出し行付き）
A14: マスター | C14: A4横 | D14: 1 | E14: 選択リスト
A15: 工種別日別 | C15: A4横 | D15: 2 | E15: 日付×工種（文字が小さいため画面用）
A16: 確認事項 | C16: A4縦 | D16: 1 | E16: 読み取り不明点・修正点
A17: 使い方 | C17: A4縦 | D17: 1 | E17: このブックの説明
A18: ○の枚数合計 | D18: =SUMIFS(D6:D17,B6:B17,"○") -> 11
A20: ■ マクロ導入後（ボタン or Alt+F8）
A21: 印刷_○のシートをプレビュー | B21: ○を付けたシートを印刷プレビューで確認
A22: 印刷_○のシートを印刷 | B22: ○を付けたシートを通常のプリンターへ一括印刷
A23: 印刷_印刷用シートを全部印刷 | B23: 印刷01〜06をまとめて印刷（○に関係なく）
A24: 印刷_全シートを印刷 | B24: ブック内の全シートを印刷
A25: 印刷_○をすべて付ける ／ 印刷_○をすべて外す | B25: B列の○を一括で切替
A27: ■ マクロなしで一括印刷する手順（Excel）
A28: 1 | B28: 印刷したい最初のシートのタブをクリック
A29: 2 | B29: Ctrlキーを押しながら他のタブをクリック（連続ならShift＋クリック）→ 選んだタブが白くなりグループ化される
A30: 3 | B30: Ctrl+P →「作業中のシートを印刷」になっていることを確認 → 印刷
A31: 4 | B31: 終わったらタブを右クリック →「シートのグループ解除」
A33: ■ Googleスプレッドシートの場合
A34: メニュー「🖨 印刷」 | B34: Apps Script（別紙 印刷メニュー_AppsScript.gs）を入れると、メニューから ○のシート／印刷用シート／全シート をPDFにしてドライブに保存し、そのままブラウザで印刷できます

Sheet 使い方
A1: 現場日報 台帳・集計ブック（第1弾 試作）
A2: 谷直美様住宅新築工事 2026/4/20〜9/2 の Keep 日報を台帳化したもの
A4: ■ このブックの構成
A5: 台帳 | B5: 元データ。1日×1人（自社）または1日×1業者 ＝ 1行。ここに追記すると他のシートはすべて自動で更新されます。
A6: マスター | B6: 現場・工程・工種・作業員・業者・機械・作業内容の選択リスト。行を追加すれば台帳の選択肢に反映されます。
A7: 印刷メニュー | B7: 印刷したいシートに○を付けて一括印刷（マクロ導入後はボタン、導入前は手動グループ印刷）。
A8: 日別集計 | B8: 日付ごとの人工（工程別・自社/業者別）と累計。A4横でA〜AG列全部を1枚幅に印刷（3枚・文字小さめ）。大きく見たい時は印刷01・02。
A9: 工種別日別 | B9: 日付×工種の人工マトリクス。列が多いので画面確認用（印刷は印刷06_週別を使用）。
A10: 確認事項 | B10: 元の日報で読み取れなかった点・修正した点の一覧。
A12: ■ 印刷用シート（赤いタブ）
A13: 印刷01_日別人工 | B13: A4縦・2枚。日付×工程の人工と自社／業者／合計。
A14: 印刷02_累計推移 | B14: A4横・3枚。工程別の累計人工と、その日の作業内容。
A15: 印刷03_グラフ | B15: A4横・1枚。累計推移グラフと日別人工グラフ。
A16: 印刷04_集計 | B16: A4横・1枚。工程別の実績と予算比較、業者別、作業員×工程。
A17: 印刷05_工種別予算 | B17: A4縦・1枚。工種ごとの実績と予算比較。
A18: 印刷06_週別 | B18: A4横・1枚。工程→工種×週の人工ヒートマップ（工程表のように読める）。
A19: まとめて印刷（Excel） | B19: 「印刷01」のタブをクリック → Shiftキーを押しながら「印刷06」のタブをクリック（赤いタブが全部選ばれる）→ Ctrl+P →「作業中のシートを印刷」で一括印刷。必要なシートだけならCtrlキーを押しながらクリックで選ぶ。印刷後はどれかのタブを右クリック→「シートのグループ解除」。
A20: まとめて印刷（Googleスプレッドシート） | B20: Googleスプレッドシートは複数シート選択印刷ができないため、印刷しないシート（台帳・マスター等）を右クリック→「シートを非表示」にしてから、Ctrl+P →「ブック全体」で印刷。印刷後に再表示。
A21: 台帳の印刷 | B21: 台帳は入力シートのため印刷用シートは作らず、台帳タブから直接印刷（A4横・見出し行付き・約6枚）。
A23: ■ 入力ルール
A24: 黄色のセル | B24: 入力してよいセル（台帳の入力列、集計の予算人工）。白いセルは数式なので触らない。
A25: 人工 | B25: 半日（午前のみ・数時間）でも 1人工 で数える（2026/9/2 決定）。人数不明の場合は空欄にして備考に理由を書く。
A26: 工種 | B26: 台帳の「工種」を選ぶと「工程」は自動で入ります。リストにない工種は直接入力し、後でマスターにも追加する。
A27: 選択リスト | B27: 台帳の 現場・区分・工種・作業員/業者名・作業内容・機械 はプルダウン。リストにないものはそのまま手入力できます（エラーになりません）。
A28: 自社 | B28: 作業員1人につき1行。同じ日に2つの工種に入った場合は工種ごとに行を分け、人工は合計1になるよう配分する。
A29: 業者 | B29: 業者1社につき1行、人工に「○人工」を入れる。個人名は分かれば備考へ。
A30: 休工 | B30: 工種「休工」で1行入れておくと、台風・養生などの記録が残ります（人工は空欄）。
A32: ■ 色の意味
A33: 緑の行 | B33: 台帳で区分＝自社
A34: 橙の行 | B34: 台帳で区分＝業者

Sheet 台帳
A1: 日付 | B1: 曜日 | C1: 現場 | D1: 区分 | E1: 工程 | F1: 工種 | G1: 作業員/業者名 | H1: 作業内容 | I1: 人工 | J1: 機械 | K1: 備考 | L1: 元記載（名寄せ前） | M1: 開始時刻 | N1: 終了時刻 | O1: 入力者 | P1: 送信日時 | Q1: 写真
A2: 46132 | B2: =IF(A2="","",CHOOSE(WEEKDAY(A2),"日","月","火","水","木","金","土")) -> 月 | C2: 谷直美様住宅新築工事 | D2: 自社 | E2: =IF(F2="","",IFERROR(INDEX(マスター!$F$5:$F$200,MATCH(F2,マスター!$E$5:$E$200,0)),"※マスター未登録")) -> 土工事 | F2: 敷地整地 | G2: 荷川取 | H2: 敷地整地 | I2: 1 | J2: ミニユンボ0.2 1台、1tローラー1台、ランマー1台 | K2: 元記載「ミニユンボ, 21台」→0.2 1台と解釈 | L2: 荷川取強、友寄
A3: 46132 | B3: =IF(A3="","",CHOOSE(WEEKDAY(A3),"日","月","火","水","木","金","土")) -> 月 | C3: 谷直美様住宅新築工事 | D3: 自社 | E3: =IF(F3="","",IFERROR(INDEX(マスター!$F$5:$F$200,MATCH(F3,マスター!$E$5:$E$200,0)),"※マスター未登録")) -> 土工事 | F3: 敷地整地 | G3: 友寄 | H3: 敷地整地 | I3: 1 | J3: ミニユンボ0.2 1台、1tローラー1台、ランマー1台 | K3: 元記載「ミニユンボ, 21台」→0.2 1台と解釈 | L3: 荷川取強、友寄
A4: 46132 | B4: =IF(A4="","",CHOOSE(WEEKDAY(A4),"日","月","火","水","木","金","土")) -> 月 | C4: 谷直美様住宅新築工事 | D4: 業者 | E4: =IF(F4="","",IFERROR(INDEX(マスター!$F$5:$F$200,MATCH(F4,マスター!$E$5:$E$200,0)),"※マスター未登録")) -> 土工事 | F4: 残土運搬 | G4: 一輝興業 | H4: 残土搬出 10tダンプ6台 | J4: 10tダンプ | K4: 人工不明（ダンプ6台分）
A5: 46133 | B5: =IF(A5="","",CHOOSE(WEEKDAY(A5),"日","月","火","水","木","金","土")) -> 火 | C5: 谷直美様住宅新築工事 | D5: 自社 | E5: =IF(F5="","",IFERROR(INDEX(マスター!$F$5:$F$200,MATCH(F5,マスター!$E$5:$E$200,0)),"※マスター未登録")) -> 土工事 | F5: 敷地整地 | G5: 荷川取 | H5: 敷地整地 | I5: 1 | J5: ミニユンボ0.2 1台、1tローラー1台、ランマー1台 | L5: 荷川取 剛、当山清
A6: 46133 | B6: =IF(A6="","",CHOOSE(WEEKDAY(A6),"日","月","火","水","木","金","土")) -> 火 | C6: 谷直美様住宅新築工事 | D6: 自社 | E6: =IF(F6="","",IFERROR(INDEX(マスター!$F$5:$F$200,MATCH(F6,マスター!$E$5:$E$200,0)),"※マスター未登録")) -> 土工事 | F6: 敷地整地 | G6: 當山 | H6: 敷地整地 | I6: 1 | J6: ミニユンボ0.2 1台、1tローラー1台、ランマー1台 | L6: 荷川取 剛、当山清
A7: 46133 | B7: =IF(A7="","",CHOOSE(WEEKDAY(A7),"日","月","火","水","木","金","土")) -> 火 | C7: 谷直美様住宅新築工事 | D7: 業者 | E7: =IF(F7="","",IFERROR(INDEX(マスター!$F$5:$F$200,MATCH(F7,マスター!$E$5:$E$200,0)),"※マスター未登録")) -> 土工事 | F7: 残土運搬 | G7: 当間均 | H7: 残土搬出 10tダンプ1台 | J7: 10tダンプ | K7: 人工不明（ダンプ1台分）
A8: 46134 | B8: =IF(A8="","",CHOOSE(WEEKDAY(A8),"日","月","火","水","木","金","土")) -> 水 | C8: 谷直美様住宅新築工事 | D8: 自社 | E8: =IF(F8="","",IFERROR(INDEX(マスター!$F$5:$F$200,MATCH(F8,マスター!$E$5:$E$200,0)),"※マスター未登録")) -> 土工事 | F8: 敷地整地 | G8: 荷川取 | H8: 敷地整地 | I8: 1 | J8: ミニユンボ0.2 1台、1tローラー1台、ランマー1台 | L8: 荷川取強、東山清
A9: 46134 | B9: =IF(A9="","",CHOOSE(WEEKDAY(A9),"日","月","火","水","木","金","土")) -> 水 | C9: 谷直美様住宅新築工事 | D9: 自社 | E9: =IF(F9="","",IFERROR(INDEX(マスター!$F$5:$F$200,MATCH(F9,マスター!$E$5:$E$200,0)),"※マスター未登録")) -> 土工事 | F9: 敷地整地 | G9: 當山 | H9: 敷地整地 | I9: 1 | J9: ミニユンボ0.2 1台、1tローラー1台、ランマー1台 | L9: 荷川取強、東山清
A10: 46134 | B10: =IF(A10="","",CHOOSE(WEEKDAY(A10),"日","月","火","水","木","金","土")) -> 水 | C10: 谷直美様住宅新築工事 | D10: 自社 | E10: =IF(F10="","",IFERROR(INDEX(マスター!$F$5:$F$200,MATCH(F10,マスター!$E$5:$E$200,0)),"※マスター未登録")) -> 土工事 | F10: 敷地整地 | G10: 友寄 | H10: 敷地整地（午前中） | I10: 1 | K10: 午前中のみ→1人工で計上
A11: 46161 | B11: =IF(A11="","",CHOOSE(WEEKDAY(A11),"日","月","火","水","木","金","土")) -> 火 | C11: 谷直美様住宅新築工事 | D11: 自社 | E11: =IF(F11="","",IFERROR(INDEX(マスター!$F$5:$F$200,MATCH(F11,マスター!$E$5:$E$200,0)),"※マスター未登録")) -> 擁壁工事 | F11: 擁壁基礎整地 | G11: 荷川取 | H11: 擁壁基礎整地、捨てコン打設1.5m3 | I11: 1 | J11: ミニユンボ0.2 1台、プレート1台
A12: 46161 | B12: =IF(A12="","",CHOOSE(WEEKDAY(A12),"日","月","火","水","木","金","土")) -> 火 | C12: 谷直美様住宅新築工事 | D12: 自社 | E12: =IF(F12="","",IFERROR(INDEX(マスター!$F$5:$F$200,MATCH(F12,マスター!$E$5:$E$200,0)),"※マスター未登録")) -> 擁壁工事 | F12: 擁壁基礎整地 | G12: 當山 | H12: 擁壁基礎整地、捨てコン打設1.5m3 | I12: 1 | J12: ミニユンボ0.2 1台、プレート1台
A13: 46162 | B13: =IF(A13="","",CHOOSE(WEEKDAY(A13),"日","月","火","水","木","金","土")) -> 水 | C13: 谷直美様住宅新築工事 | D13: 自社 | E13: =IF(F13="","",IFERROR(INDEX(マスター!$F$5:$F$200,MATCH(F13,マスター!$E$5:$E$200,0)),"※マスター未登録")) -> 擁壁工事 | F13: 擁壁基礎整地 | G13: 荷川取 | H13: 擁壁基礎整地 | I13: 1 | J13: ミニユンボ0.2 1台、プレート1台 | K13: 元記載「5月19日水曜日」→5/20（水）に修正
A14: 46162 | B14: =IF(A14="","",CHOOSE(WEEKDAY(A14),"日","月","火","水","木","金","土")) -> 水 | C14: 谷直美様住宅新築工事 | D14: 自社 | E14: =IF(F14="","",IFERROR(INDEX(マスター!$F$5:$F$200,MATCH(F14,マスター!$E$5:$E$200,0)),"※マスター未登録")) -> 擁壁工事 | F14: 擁壁基礎整地 | G14: 當山 | H14: 擁壁基礎整地 | I14: 1 | J14: ミニユンボ0.2 1台、プレート1台 | K14: 元記載「5月19日水曜日」→5/20（水）に修正
A15: 46163 | B15: =IF(A15="","",CHOOSE(WEEKDAY(A15),"日","月","火","水","木","金","土")) -> 木 | C15: 谷直美様住宅新築工事 | D15: 自社 | E15: =IF(F15="","",IFERROR(INDEX(マスター!$F$5:$F$200,MATCH(F15,マスター!$E$5:$E$200,0)),"※マスター未登録")) -> 擁壁工事 | F15: 擁壁基礎整地 | G15: 荷川取 | H15: 擁壁基礎整地 | I15: 1 | J15: ミニユンボ0.2 1台、プレート1台
A16: 46163 | B16: =IF(A16="","",CHOOSE(WEEKDAY(A16),"日","月","火","水","木","金","土")) -> 木 | C16: 谷直美様住宅新築工事 | D16: 自社 | E16: =IF(F16="","",IFERROR(INDEX(マスター!$F$5:$F$200,MATCH(F16,マスター!$E$5:$E$200,0)),"※マスター未登録")) -> 擁壁工事 | F16: 擁壁基礎整地 | G16: 當山 | H16: 擁壁基礎整地 | I16: 1 | J16: ミニユンボ0.2 1台、プレート1台
A17: 46185 | B17: =IF(A17="","",CHOOSE(WEEKDAY(A17),"日","月","火","水","木","金","土")) -> 金 | C17: 谷直美様住宅新築工事 | D17: 業者 | E17: =IF(F17="","",IFERROR(INDEX(マスター!$F$5:$F$200,MATCH(F17,マスター!$E$5:$E$200,0)),"※マスター未登録")) -> 地盤改良工事 | F17: 地盤改良 | G17: グランド技研 | H17: 資材搬入 | I17: 4
A18: 46186 | B18: =IF(A18="","",CHOOSE(WEEKDAY(A18),"日","月","火","水","木","金","土")) -> 土 | C18: 谷直美様住宅新築工事 | D18: 業者 | E18: =IF(F18="","",IFERROR(INDEX(マスター!$F$5:$F$200,MATCH(F18,マスター!$E$5:$E$200,0)),"※マスター未登録")) -> 地盤改良工事 | F18: 地盤改良 | G18: グランド技研 | H18: 資材搬入 | I18: 4
A19: 46188 | B19: =IF(A19="","",CHOOSE(WEEKDAY(A19),"日","月","火","水","木","金","土")) -> 月 | C19: 谷直美様住宅新築工事 | D19: 業者 | E19: =IF(F19="","",IFERROR(INDEX(マスター!$F$5:$F$200,MATCH(F19,マスター!$E$5:$E$200,0)),"※マスター未登録")) -> 地盤改良工事 | F19: 地盤改良 | G19: グランド技研 | H19: 地盤改良工事 作業開始 | I19: 4
A20: 46189 | B20: =IF(A20="","",CHOOSE(WEEKDAY(A20),"日","月","火","水","木","金","土")) -> 火 | C20: 谷直美様住宅新築工事 | D20: 業者 | E20: =IF(F20="","",IFERROR(INDEX(マスター!$F$5:$F$200,MATCH(F20,マスター!$E$5:$E$200,0)),"※マスター未登録")) -> 地盤改良工事 | F20: 地盤改良 | G20: グランド技研 | H20: 地盤改良（雨のため半日） | I20: 3 | K20: 半日→1人工で計上
A21: 46190 | B21: =IF(A21="","",CHOOSE(WEEKDAY(A21),"日","月","火","水","木","金","土")) -> 水 | C21: 谷直美様住宅新築工事 | D21: 業者 | E21: =IF(F21="","",IFERROR(INDEX(マスター!$F$5:$F$200,MATCH(F21,マスター!$E$5:$E$200,0)),"※マスター未登録")) -> 地盤改良工事 | F21: 地盤改良 | G21: グランド技研 | H21: 地盤改良作業 | I21: 3
A22: 46191 | B22: =IF(A22="","",CHOOSE(WEEKDAY(A22),"日","月","火","水","木","金","土")) -> 木 | C22: 谷直美様住宅新築工事 | D22: 業者 | E22: =IF(F22="","",IFERROR(INDEX(マスター!$F$5:$F$200,MATCH(F22,マスター!$E$5:$E$200,0)),"※マスター未登録")) -> 地盤改良工事 | F22: 地盤改良 | G22: グランド技研 | H22: 地盤改良作業 | I22: 3
A23: 46192 | B23: =IF(A23="","",CHOOSE(WEEKDAY(A23),"日","月","火","水","木","金","土")) -> 金 | C23: 谷直美様住宅新築工事 | D23: 業者 | E23: =IF(F23="","",IFERROR(INDEX(マスター!$F$5:$F$200,MATCH(F23,マスター!$E$5:$E$200,0)),"※マスター未登録")) -> 地盤改良工事 | F23: 地盤改良 | G23: グランド技研 | H23: 地盤改良作業（この日で作業終了） | I23: 3
A24: 46195 | B24: =IF(A24="","",CHOOSE(WEEKDAY(A24),"日","月","火","水","木","金","土")) -> 月 | C24: 谷直美様住宅新築工事 | D24: 業者 | E24: =IF(F24="","",IFERROR(INDEX(マスター!$F$5:$F$200,MATCH(F24,マスター!$E$5:$E$200,0)),"※マスター未登録")) -> 地盤改良工事 | F24: 地盤改良 | G24: グランド技研 | H24: 地盤改良機材 解体片付け | I24: 3
A25: 46196 | B25: =IF(A25="","",CHOOSE(WEEKDAY(A25),"日","月","火","水","木","金","土")) -> 火 | C25: 谷直美様住宅新築工事 | D25: 業者 | E25: =IF(F25="","",IFERROR(INDEX(マスター!$F$5:$F$200,MATCH(F25,マスター!$E$5:$E$200,0)),"※マスター未登録")) -> 地盤改良工事 | F25: 地盤改良 | G25: グランド技研 | H25: 地盤改良機材 解体片付け（全作業終了） | I25: 3
A26: 46197 | B26: =IF(A26="","",CHOOSE(WEEKDAY(A26),"日","月","火","水","木","金","土")) -> 水 | C26: 谷直美様住宅新築工事 | D26: 自社 | E26: =IF(F26="","",IFERROR(INDEX(マスター!$F$5:$F$200,MATCH(F26,マスター!$E$5:$E$200,0)),"※マスター未登録")) -> 基礎工事 | F26: 基礎掘削 | G26: 荷川取 | H26: 掘削作業開始（掘削前整地）、建物位置出し | I26: 1 | J26: ミニユンボ0.2 1台 | L26: 荷川取強、洞爺清、友寄司
A27: 46197 | B27: =IF(A27="","",CHOOSE(WEEKDAY(A27),"日","月","火","水","木","金","土")) -> 水 | C27: 谷直美様住宅新築工事 | D27: 自社 | E27: =IF(F27="","",IFERROR(INDEX(マスター!$F$5:$F$200,MATCH(F27,マスター!$E$5:$E$200,0)),"※マスター未登録")) -> 基礎工事 | F27: 基礎掘削 | G27: 當山 | H27: 掘削作業開始（掘削前整地）、建物位置出し | I27: 1 | J27: ミニユンボ0.2 1台 | L27: 荷川取強、洞爺清、友寄司
A28: 46197 | B28: =IF(A28="","",CHOOSE(WEEKDAY(A28),"日","月","火","水","木","金","土")) -> 水 | C28: 谷直美様住宅新築工事 | D28: 自社 | E28: =IF(F28="","",IFERROR(INDEX(マスター!$F$5:$F$200,MATCH(F28,マスター!$E$5:$E$200,0)),"※マスター未登録")) -> 基礎工事 | F28: 基礎掘削 | G28: 友寄 | H28: 掘削作業開始（掘削前整地）、建物位置出し | I28: 1 | J28: ミニユンボ0.2 1台 | L28: 荷川取強、洞爺清、友寄司
A29: 46197 | B29: =IF(A29="","",CHOOSE(WEEKDAY(A29),"日","月","火","水","木","金","土")) -> 水 | C29: 谷直美様住宅新築工事 | D29: 自社 | E29: =IF(F29="","",IFERROR(INDEX(マスター!$F$5:$F$200,MATCH(F29,マスター!$E$5:$E$200,0)),"※マスター未登録")) -> 準備・仮設工事 | F29: 仮設トイレ | G29: 荷川取 | H29: 仮設トイレ設置 | K29: 同日の掘削作業と兼務のため人工は掘削側に計上
A30: 46198 | B30: =IF(A30="","",CHOOSE(WEEKDAY(A30),"日","月","火","水","木","金","土")) -> 木 | C30: 谷直美様住宅新築工事 | D30: 自社 | E30: =IF(F30="","",IFERROR(INDEX(マスター!$F$5:$F$200,MATCH(F30,マスター!$E$5:$E$200,0)),"※マスター未登録")) -> 基礎工事 | F30: 基礎掘削 | G30: 荷川取 | H30: 基礎掘削作業 | I30: 1 | J30: ミニユンボ0.2 1台、プレート1台 | K30: 元記載「6月24日木曜日」→6/25（木）に修正 | L30: 荷川取、東山、友寄
A31: 46198 | B31: =IF(A31="","",CHOOSE(WEEKDAY(A31),"日","月","火","水","木","金","土")) -> 木 | C31: 谷直美様住宅新築工事 | D31: 自社 | E31: =IF(F31="","",IFERROR(INDEX(マスター!$F$5:$F$200,MATCH(F31,マスター!$E$5:$E$200,0)),"※マスター未登録")) -> 基礎工事 | F31: 基礎掘削 | G31: 當山 | H31: 基礎掘削作業 | I31: 1 | J31: ミニユンボ0.2 1台、プレート1台 | K31: 元記載「6月24日木曜日」→6/25（木）に修正 | L31: 荷川取、東山、友寄
A32: 46198 | B32: =IF(A32="","",CHOOSE(WEEKDAY(A32),"日","月","火","水","木","金","土")) -> 木 | C32: 谷直美様住宅新築工事 | D32: 自社 | E32: =IF(F32="","",IFERROR(INDEX(マスター!$F$5:$F$200,MATCH(F32,マスター!$E$5:$E$200,0)),"※マスター未登録")) -> 基礎工事 | F32: 基礎掘削 | G32: 友寄 | H32: 基礎掘削作業 | I32: 1 | J32: ミニユンボ0.2 1台、プレート1台 | K32: 元記載「6月24日木曜日」→6/25（木）に修正 | L32: 荷川取、東山、友寄
A33: 46199 | B33: =IF(A33="","",CHOOSE(WEEKDAY(A33),"日","月","火","水","木","金","土")) -> 金 | C33: 谷直美様住宅新築工事 | D33: 自社 | E33: =IF(F33="","",IFERROR(INDEX(マスター!$F$5:$F$200,MATCH(F33,マスター!$E$5:$E$200,0)),"※マスター未登録")) -> 基礎工事 | F33: 基礎掘削 | G33: 荷川取 | H33: 基礎掘削作業 | I33: 1 | J33: ミニユンボ0.2 1台、プレート1台 | K33: 元記載「6月25日金曜日」→6/26（金）に修正 | L33: 荷川取り、当山
A34: 46199 | B34: =IF(A34="","",CHOOSE(WEEKDAY(A34),"日","月","火","水","木","金","土")) -> 金 | C34: 谷直美様住宅新築工事 | D34: 自社 | E34: =IF(F34="","",IFERROR(INDEX(マスター!$F$5:$F$200,MATCH(F34,マスター!$E$5:$E$200,0)),"※マスター未登録")) -> 基礎工事 | F34: 基礎掘削 | G34: 當山 | H34: 基礎掘削作業 | I34: 1 | J34: ミニユンボ0.2 1台、プレート1台 | K34: 元記載「6月25日金曜日」→6/26（金）に修正 | L34: 荷川取り、当山
A35: 46200 | B35: =IF(A35="","",CHOOSE(WEEKDAY(A35),"日","月","火","水","木","金","土")) -> 土 | C35: 谷直美様住宅新築工事 | D35: 自社 | E35: =IF(F35="","",IFERROR(INDEX(マスター!$F$5:$F$200,MATCH(F35,マスター!$E$5:$E$200,0)),"※マスター未登録")) -> その他 | F35: 休工 | H35: 台風のため作業中断（6/26〜28） | K35: 元記載「6月26日から28日まで台風」。6/26は作業記録ありのため6/27〜28を休工とした
A36: 46201 | B36: =IF(A36="","",CHOOSE(WEEKDAY(A36),"日","月","火","水","木","金","土")) -> 日 | C36: 谷直美様住宅新築工事 | D36: 自社 | E36: =IF(F36="","",IFERROR(INDEX(マスター!$F$5:$F$200,MATCH(F36,マスター!$E$5:$E$200,0)),"※マスター未登録")) -> その他 | F36: 休工 | H36: 台風のため作業中断
A37: 46202 | B37: =IF(A37="","",CHOOSE(WEEKDAY(A37),"日","月","火","水","木","金","土")) -> 月 | C37: 谷直美様住宅新築工事 | D37: 自社 | E37: =IF(F37="","",IFERROR(INDEX(マスター!$F$5:$F$200,MATCH(F37,マスター!$E$5:$E$200,0)),"※マスター未登録")) -> 基礎工事 | F37: 基礎掘削 | G37: 荷川取 | H37: 残りの掘削、白蟻防除散布・土壌処理、土間防湿ポリシート敷込み、捨てコン打設2m3 | I37: 1 | J37: ミニユンボ0.2 1台、プレート1台 | L37: 荷川取、東山、宮城、友寄
A38: 46202 | B38: =IF(A38="","",CHOOSE(WEEKDAY(A38),"日","月","火","水","木","金","土")) -> 月 | C38: 谷直美様住宅新築工事 | D38: 自社 | E38: =IF(F38="","",IFERROR(INDEX(マスター!$F$5:$F$200,MATCH(F38,マスター!$E$5:$E$200,0)),"※マスター未登録")) -> 基礎工事 | F38: 基礎掘削 | G38: 當山 | H38: 残りの掘削、白蟻防除散布・土壌処理、土間防湿ポリシート敷込み、捨てコン打設2m3 | I38: 1 | J38: ミニユンボ0.2 1台、プレート1台 | L38: 荷川取、東山、宮城、友寄
A39: 46202 | B39: =IF(A39="","",CHOOSE(WEEKDAY(A39),"日","月","火","水","木","金","土")) -> 月 | C39: 谷直美様住宅新築工事 | D39: 自社 | E39: =IF(F39="","",IFERROR(INDEX(マスター!$F$5:$F$200,MATCH(F39,マスター!$E$5:$E$200,0)),"※マスター未登録")) -> 基礎工事 | F39: 基礎掘削 | G39: 宮城 | H39: 残りの掘削、白蟻防除散布・土壌処理、土間防湿ポリシート敷込み、捨てコン打設2m3 | I39: 1 | J39: ミニユンボ0.2 1台、プレート1台 | L39: 荷川取、東山、宮城、友寄
A40: 46202 | B40: =IF(A40="","",CHOOSE(WEEKDAY(A40),"日","月","火","水","木","金","土")) -> 月 | C40: 谷直美様住宅新築工事 | D40: 自社 | E40: =IF(F40="","",IFERROR(INDEX(マスター!$F$5:$F$200,MATCH(F40,マスター!$E$5:$E$200,0)),"※マスター未登録")) -> 基礎工事 | F40: 基礎掘削 | G40: 友寄 | H40: 残りの掘削、白蟻防除散布・土壌処理、土間防湿ポリシート敷込み、捨てコン打設2m3 | I40: 1 | J40: ミニユンボ0.2 1台、プレート1台 | L40: 荷川取、東山、宮城、友寄
...

Sheet マスター
A1: マスター（選択リスト）
A2: 行を追加すると台帳のプルダウンに反映されます（各列 200 行まで見ています）。工種には必ず工程を対で入れてください。
A4: 現場 | C4: 工程 | E4: 工種 | F4: 工程（工種の親） | H4: 作業員（自社） | J4: 業者 | L4: 機械 | N4: 作業内容 | P4: 区分
A5: 谷直美様住宅新築工事 | C5: 準備・仮設工事 | E5: 仮設工事 | F5: 準備・仮設工事 | H5: 荷川取 | J5: 一輝興業 | L5: ミニユンボ0.1 | N5: 15時より外壁下地ノボパン釘打ち、内部間柱筋交い・玄関廻り間柱設置 | P5: 自社
C6: 土工事 | E6: 仮設トイレ | F6: 準備・仮設工事 | H6: 當山 | J6: 当間均 | L6: ミニユンボ0.2 | N6: クレーン車15t 1台（1日） | P6: 業者
C7: 擁壁工事 | E7: 敷地整地 | F7: 土工事 | H7: 宮城 | J7: グランド技研 | L7: ユンボ0.4 | N7: クロス仕上げ張り
C8: 地盤改良工事 | E8: 残土運搬 | F8: 土工事 | H8: 友寄 | J8: 稲嶺（屋根・外壁） | L8: 2tダンプ | N8: クロス仕上げ張り（午後2時まで）
C9: 基礎工事 | E9: 擁壁基礎整地 | F9: 擁壁工事 | H9: 上原 | J9: 電気業者 | L9: クラッシャー | N9: クロス前穴あけ
C10: 木工事 | E10: 地盤改良 | F10: 地盤改良工事 | H10: 山里 | J10: 外壁サイディング業者 | L10: 1tローラー | N10: ノボパン張り
C11: 屋根・外壁工事 | E11: 基礎掘削 | F11: 基礎工事 | H11: 平良 | J11: コーキング業者 | L11: ランマー | N11: ノボパン張り（午前中DMM）
C12: 内装仕上げ工事 | E12: 基礎型枠 | F12: 基礎工事 | J12: 左官業者 | L12: プレート | N12: フローリング張り
C13: 電気設備工事 | E13: 鉄筋工事 | F13: 基礎工事 | J13: ポンプ業者 | L13: 10tダンプ | N13: ブロック打ち出し及び検査前片付け、検査11時（設計 斉藤参加）
C14: 給排水設備工事 | E14: 基礎コンクリート打設 | F14: 基礎工事 | J14: 鉄筋業者 | L14: ユニック | N14: ポンプセット
C15: 外構工事 | E15: 左官工事 | F15: 基礎工事 | J15: 設備業者 | L15: クレーン車15t | N15: ポンプ車
C16: その他 | E16: ポンプ工事 | F16: 基礎工事 | J16: ユニットバス業者 | L16: ポンプ車 | N16: ユニットバス設置指導（午後より2人応援）
E17: 基礎型枠解体・片付け | F17: 基礎工事 | J17: クレーン業者 | L17: 生コン車 | N17: 上部 電気業者間違え箇所 張り直し
E18: 土台・床組 | F18: 木工事 | J18: 生コン | N18: 仮設トイレ設置
E19: 上棟 | F19: 木工事 | J19: 屋根業者 | N19: 作業内容の記載なし
E20: 軸組・下地 | F20: 木工事 | J20: 内装業者（クロス） | N20: 作業内容の記載なし（前後から天井下地と推定）
E21: 外壁下地 | F21: 木工事 | J21: 大工ヨナハラ | N21: 作業内容の記載なし（前日の続きと推定）
E22: サッシ取付 | F22: 木工事 | J22: 足場業者 | N22: 作業員・作業内容の記載なし
E23: 断熱工事 | F23: 木工事 | J23: ガス業者 | N23: 内部作業（作業内容記載なし）
E24: 天井下地 | F24: 木工事 | J24: 水道業者 | N24: 内部壁PBボード張り
E25: 内装下地（PB） | F25: 木工事 | J25: タイル業者 | N25: 内部壁PBボード張り・ユニットバス設置
E26: 造作（框・幅木） | F26: 木工事 | N26: 内部壁PBボード張り・断熱材シート張り
E27: 屋根工事 | F27: 屋根・外壁工事 | N27: 内部壁PBボード張り・現場台風対策片付け
E28: 外壁防水シート | F28: 屋根・外壁工事 | N28: 内部壁PBボード張り（午前 沖銀防風対策）
E29: 外壁サイディング | F29: 屋根・外壁工事 | N29: 内部床ボンド清掃
E30: コーキング | F30: 屋根・外壁工事 | N30: 午後より玄関ポーチ・土間吊り作業
E31: 足場 | F31: 屋根・外壁工事 | N31: 台風のため作業中断
E32: クロス工事 | F32: 内装仕上げ工事 | N32: 台風のため作業中断（6/26〜28）
E33: 床仕上げ（フローリング） | F33: 内装仕上げ工事 | N33: 台風のため終日休み
E34: タイル工事 | F34: 内装仕上げ工事 | N34: 同上（3時まで沖縄銀行 台風巻上げ）
E35: 電気配線 | F35: 電気設備工事 | N35: 同上（3時間）
E36: 電気器具取付 | F36: 電気設備工事 | N36: 同上（午前中 かりゆしファーム土出し）
E37: 設備配管 | F37: 給排水設備工事 | N37: 同上（午後2〜3時間）
... E45: 休工 | F45: その他 | N45: 地盤改良機材 解体片付け
N46: 地盤改良機材 解体片付け（全作業終了）
N47: 地盤改良（雨のため半日）
N48: 型枠組
...

Sheet 日別集計
A1: 日別集計（工程別人工と累計）
A2: 台帳から自動集計。日付は 4/20〜9/2 の全日（休工日も表示）。
A4: 日付 | B4: 曜日 | C4: 準備・仮設工事 | D4: 土工事 | E4: 擁壁工事 | F4: 地盤改良工事 | G4: 基礎工事 | H4: 木工事 | I4: 屋根・外壁工事 | J4: 内装仕上げ工事 | K4: 電気設備工事 | L4: 給排水設備工事 | M4: 外構工事 | N4: その他 | O4: 自社 | P4: 業者 | Q4: 合計 | R4: 累計 準備・仮設工事 | S4: 累計 土工事 | T4: 累計 擁壁工事 | U4: 累計 地盤改良工事 | V4: 累計 基礎工事 | W4: 累計 木工事 | X4: 累計 屋根・外壁工事 | Y4: 累計 内装仕上げ工事 | Z4: 累計 電気設備工事 | AA4: 累計 給排水設備工事 | AB4: 累計 外構工事 | AC4: 累計 その他 | AD4: 累計 自社 | AE4: 累計 業者 | AF4: 累計 合計 | AG4: その日の作業内容（自社）
A5: 46132 | B5: =CHOOSE(WEEKDAY(A5),"日","月","火","水","木","金","土") -> 月 | C5: =SUMIFS(台帳!$I$2:$I$2000,台帳!$A$2:$A$2000,$A5,台帳!$E$2:$E$2000,C$4) -> 0 | D5: =SUMIFS(台帳!$I$2:$I$2000,台帳!$A$2:$A$2000,$A5,台帳!$E$2:$E$2000,D$4) -> 2 | E5: =SUMIFS(台帳!$I$2:$I$2000,台帳!$A$2:$A$2000,$A5,台帳!$E$2:$E$2000,E$4) -> 0 | F5: =SUMIFS(台帳!$I$2:$I$2000,台帳!$A$2:$A$2000,$A5,台帳!$E$2:$E$2000,F$4) -> 0 | G5: =SUMIFS(台帳!$I$2:$I$2000,台帳!$A$2:$A$2000,$A5,台帳!$E$2:$E$2000,G$4) -> 0 | H5: =SUMIFS(台帳!$I$2:$I$2000,台帳!$A$2:$A$2000,$A5,台帳!$E$2:$E$2000,H$4) -> 0 | I5: =SUMIFS(台帳!$I$2:$I$2000,台帳!$A$2:$A$2000,$A5,台帳!$E$2:$E$2000,I$4) -> 0 | J5: =SUMIFS(台帳!$I$2:$I$2000,台帳!$A$2:$A$2000,$A5,台帳!$E$2:$E$2000,J$4) -> 0 | ... N5: =SUMIFS(台帳!$I$2:$I$2000,台帳!$A$2:$A$2000,$A5,台帳!$E$2:$E$2000,N$4) -> 0 | O5: =SUMIFS(台帳!$I$2:$I$2000,台帳!$A$2:$A$2000,$A5,台帳!$D$2:$D$2000,"自社") -> 2 | P5: =SUMIFS(台帳!$I$2:$I$2000,台帳!$A$2:$A$2000,$A5,台帳!$D$2:$D$2000,"業者") -> 0 | Q5: =SUM(C5:N5) -> 2 | R5: =0+C5 -> 0 | S5: =0+D5 -> 2 | T5: =0+E5 -> 0 | U5: =0+F5 -> 0 | V5: =0+G5 -> 0 | W5: =0+H5 -> 0 | X5: =0+I5 -> 0 | Y5: =0+J5 -> 0 | ... AF5: =0+Q5 -> 2 | AG5: =IFERROR(INDEX(台帳!$H$2:$H$2000,MATCH($A5,台帳!$A$2:$A$2000,0)),"") -> 敷地整地
A6: 46133 | B6: =CHOOSE(WEEKDAY(A6),"日","月","火","水","木","金","土") -> 火 | C6: =SUMIFS(台帳!$I$2:$I$2000,台帳!$A$2:$A$2000,$A6,台帳!$E$2:$E$2000,C$4) -> 0 | D6: =SUMIFS(台帳!$I$2:$I$2000,台帳!$A$2:$A$2000,$A6,台帳!$E$2:$E$2000,D$4) -> 2 | E6: =SUMIFS(台帳!$I$2:$I$2000,台帳!$A$2:$A$2000,$A6,台帳!$E$2:$E$2000,E$4) -> 0 | F6: =SUMIFS(台帳!$I$2:$I$2000,台帳!$A$2:$A$2000,$A6,台帳!$E$2:$E$2000,F$4) -> 0 | G6: =SUMIFS(台帳!$I$2:$I$2000,台帳!$A$2:$A$2000,$A6,台帳!$E$2:$E$2000,G$4) -> 0 | H6: =SUMIFS(台帳!$I$2:$I$2000,台帳!$A$2:$A$2000,$A6,台帳!$E$2:$E$2000,H$4) -> 0 | I6: =SUMIFS(台帳!$I$2:$I$2000,台帳!$A$2:$A$2000,$A6,台帳!$E$2:$E$2000,I$4) -> 0 | J6: =SUMIFS(台帳!$I$2:$I$2000,台帳!$A$2:$A$2000,$A6,台帳!$E$2:$E$2000,J$4) -> 0 | ... N6: =SUMIFS(台帳!$I$2:$I$2000,台帳!$A$2:$A$2000,$A6,台帳!$E$2:$E$2000,N$4) -> 0 | O6: =SUMIFS(台帳!$I$2:$I$2000,台帳!$A$2:$A$2000,$A6,台帳!$D$2:$D$2000,"自社") -> 2 | P6: =SUMIFS(台帳!$I$2:$I$2000,台帳!$A$2:$A$2000,$A6,台帳!$D$2:$D$2000,"業者") -> 0 | Q6: =SUM(C6:N6) -> 2 | R6: =R5+C6 -> 0 | S6: =S5+D6 -> 4 | T6: =T5+E6 -> 0 | U6: =U5+F6 -> 0 | V6: =V5+G6 -> 0 | W6: =W5+H6 -> 0 | X6: =X5+I6 -> 0 | Y6: =Y5+J6 -> 0 | ... AF6: =AF5+Q6 -> 4 | AG6: =IFERROR(INDEX(台帳!$H$2:$H$2000,MATCH($A6,台帳!$A$2:$A$2000,0)),"") -> 敷地整地
A7: 46134 | B7: =CHOOSE(WEEKDAY(A7),"日","月","火","水","木","金","土") -> 水 | C7: =SUMIFS(台帳!$I$2:$I$2000,台帳!$A$2:$A$2000,$A7,台帳!$E$2:$E$2000,C$4) -> 0 | D7: =SUMIFS(台帳!$I$2:$I$2000,台帳!$A$2:$A$2000,$A7,台帳!$E$2:$E$2000,D$4) -> 3 | E7: =SUMIFS(台帳!$I$2:$I$2000,台帳!$A$2:$A$2000,$A7,台帳!$E$2:$E$2000,E$4) -> 0 | F7: =SUMIFS(台帳!$I$2:$I$2000,台帳!$A$2:$A$2000,$A7,台帳!$E$2:$E$2000,F$4) -> 0 | G7: =SUMIFS(台帳!$I$2:$I$2000,台帳!$A$2:$A$2000,$A7,台帳!$E$2:$E$2000,G$4) -> 0 | H7: =SUMIFS(台帳!$I$2:$I$2000,台帳!$A$2:$A$2000,$A7,台帳!$E$2:$E$2000,H$4) -> 0 | I7: =SUMIFS(台帳!$I$2:$I$2000,台帳!$A$2:$A$2000,$A7,台帳!$E$2:$E$2000,I$4) -> 0 | J7: =SUMIFS(台帳!$I$2:$I$2000,台帳!$A$2:$A$2000,$A7,台帳!$E$2:$E$2000,J$4) -> 0 | ... N7: =SUMIFS(台帳!$I$2:$I$2000,台帳!$A$2:$A$2000,$A7,台帳!$E$2:$E$2000,N$4) -> 0 | O7: =SUMIFS(台帳!$I$2:$I$2000,台帳!$A$2:$A$2000,$A7,台帳!$D$2:$D$2000,"自社") -> 3 | P7: =SUMIFS(台帳!$I$2:$I$2000,台帳!$A$2:$A$2000,$A7,台帳!$D$2:$D$2000,"業者") -> 0 | Q7: =SUM(C7:N7) -> 3 | R7: =R6+C7 -> 0 | S7: =S6+D7 -> 7 | T7: =T6+E7 -> 0 | U7: =U6+F7 -> 0 | V7: =V6+G7 -> 0 | W7: =W6+H7 -> 0 | X7: =X6+I7 -> 0 | Y7: =Y6+J7 -> 0 | ... AF7: =AF6+Q7 -> 7 | AG7: =IFERROR(INDEX(台帳!$H$2:$H$2000,MATCH($A7,台帳!$A$2:$A$2000,0)),"") -> 敷地整地
A8: 46135 | B8: =CHOOSE(WEEKDAY(A8),"日","月","火","水","木","金","土") -> 木 | C8: =SUMIFS(台帳!$I$2:$I$2000,台帳!$A$2:$A$2000,$A8,台帳!$E$2:$E$2000,C$4) -> 0 | D8: =SUMIFS(台帳!$I$2:$I$2000,台帳!$A$2:$A$2000,$A8,台帳!$E$2:$E$2000,D$4) -> 0 | E8: =SUMIFS(台帳!$I$2:$I$2000,台帳!$A$2:$A$2000,$A8,台帳!$E$2:$E$2000,E$4) -> 0 | F8: =SUMIFS(台帳!$I$2:$I$2000,台帳!$A$2:$A$2000,$A8,台帳!$E$2:$E$2000,F$4) -> 0 | G8: =SUMIFS(台帳!$I$2:$I$2000,台帳!$A$2:$A$2000,$A8,台帳!$E$2:$E$2000,G$4) -> 0 | H8: =SUMIFS(台帳!$I$2:$I$2000,台帳!$A$2:$A$2000,$A8,台帳!$E$2:$E$2000,H$4) -> 0 | I8: =SUMIFS(台帳!$I$2:$I$2000,台帳!$A$2:$A$2000,$A8,台帳!$E$2:$E$2000,I$4) -> 0 | J8: =SUMIFS(台帳!$I$2:$I$2000,台帳!$A$2:$A$2000,$A8,台帳!$E$2:$E$2000,J$4) -> 0 | ... N8: =SUMIFS(台帳!$I$2:$I$2000,台帳!$A$2:$A$2000,$A8,台帳!$E$2:$E$2000,N$4) -> 0 | O8: =SUMIFS(台帳!$I$2:$I$2000,台帳!$A$2:$A$2000,$A8,台帳!$D$2:$D$2000,"自社") -> 0 | P8: =SUMIFS(台帳!$I$2:$I$2000,台帳!$A$2:$A$2000,$A8,台帳!$D$2:$D$2000,"業者") -> 0 | Q8: =SUM(C8:N8) -> 0 | R8: =R7+C8 -> 0 | S8: =S7+D8 -> 7 | T8: =T7+E8 -> 0 | U8: =U7+F8 -> 0 | V8: =V7+G8 -> 0 | W8: =W7+H8 -> 0 | X8: =X7+I8 -> 0 | Y8: =Y7+J8 -> 0 | ... AF8: =AF7+Q8 -> 7 | AG8: =IFERROR(INDEX(台帳!$H$2:$H$2000,MATCH($A8,台帳!$A$2:$A$2000,0)),"")
A9: 46136 | B9: =CHOOSE(WEEKDAY(A9),"日","月","火","水","木","金","土") -> 金 | C9: =SUMIFS(台帳!$I$2:$I$2000,台帳!$A$2:$A$2000,$A9,台帳!$E$2:$E$2000,C$4) -> 0 | D9: =SUMIFS(台帳!$I$2:$I$2000,台帳!$A$2:$A$2000,$A9,台帳!$E$2:$E$2000,D$4) -> 0 | E9: =SUMIFS(台帳!$I$2:$I$2000,台帳!$A$2:$A$2000,$A9,台帳!$E$2:$E$2000,E$4) -> 0 | F9: =SUMIFS(台帳!$I$2:$I$2000,台帳!$A$2:$A$2000,$A9,台帳!$E$2:$E$2000,F$4) -> 0 | G9: =SUMIFS(台帳!$I$2:$I$2000,台帳!$A$2:$A$2000,$A9,台帳!$E$2:$E$2000,G$4) -> 0 | H9: =SUMIFS(台帳!$I$2:$I$2000,台帳!$A$2:$A$2000,$A9,台帳!$E$2:$E$2000,H$4) -> 0 | I9: =SUMIFS(台帳!$I$2:$I$2000,台帳!$A$2:$A$2000,$A9,台帳!$E$2:$E$2000,I$4) -> 0 | J9: =SUMIFS(台帳!$I$2:$I$2000,台帳!$A$2:$A$2000,$A9,台帳!$E$2:$E$2000,J$4) -> 0 | ... N9: =SUMIFS(台帳!$I$2:$I$2000,台帳!$A$2:$A$2000,$A9,台帳!$E$2:$E$2000,N$4) -> 0 | O9: =SUMIFS(台帳!$I$2:$I$2000,台帳!$A$2:$A$2000,$A9,台帳!$D$2:$D$2000,"自社") -> 0 | P9: =SUMIFS(台帳!$I$2:$I$2000,台帳!$A$2:$A$2000,$A9,台帳!$D$2:$D$2000,"業者") -> 0 | Q9: =SUM(C9:N9) -> 0 | R9: =R8+C9 -> 0 | S9: =S8+D9 -> 7 | T9: =T8+E9 -> 0 | U9: =U8+F9 -> 0 | V9: =V8+G9 -> 0 | W9: =W8+H9 -> 0 | X9: =X8+I9 -> 0 | Y9: =Y8+J9 -> 0 | ... AF9: =AF8+Q9 -> 7 | AG9: =IFERROR(INDEX(台帳!$H$2:$H$2000,MATCH($A9,台帳!$A$2:$A$2000,0)),"")
A10: 46137 | B10: =CHOOSE(WEEKDAY(A10),"日","月","火","水","木","金","土") -> 土 | C10: =SUMIFS(台帳!$I$2:$I$2000,台帳!$A$2:$A$2000,$A10,台帳!$E$2:$E$2000,C$4) -> 0 | D10: =SUMIFS(台帳!$I$2:$I$2000,台帳!$A$2:$A$2000,$A10,台帳!$E$2:$E$2000,D$4) -> 0 | E10: =SUMIFS(台帳!$I$2:$I$2000,台帳!$A$2:$A$2000,$A10,台帳!$E$2:$E$2000,E$4) -> 0 | F10: =SUMIFS(台帳!$I$2:$I$2000,台帳!$A$2:$A$2000,$A10,台帳!$E$2:$E$2000,F$4) -> 0 | G10: =SUMIFS(台帳!$I$2:$I$2000,台帳!$A$2:$A$2000,$A10,台帳!$E$2:$E$2000,G$4) -> 0 | H10: =SUMIFS(台帳!$I$2:$I$2000,台帳!$A$2:$A$2000,$A10,台帳!$E$2:$E$2000,H$4) -> 0 | I10: =SUMIFS(台帳!$I$2:$I$2000,台帳!$A$2:$A$2000,$A10,台帳!$E$2:$E$2000,I$4) -> 0 | J10: =SUMIFS(台帳!$I$2:$I$2000,台帳!$A$2:$A$2000,$A10,台帳!$E$2:$E$2000,J$4) -> 0 | ... N10: =SUMIFS(台帳!$I$2:$I$2000,台帳!$A$2:$A$2000,$A10,台帳!$E$2:$E$2000,N$4) -> 0 | O10: =SUMIFS(台帳!$I$2:$I$2000,台帳!$A$2:$A$2000,$A10,台帳!$D$2:$D$2000,"自社") -> 0 | P10: =SUMIFS(台帳!$I$2:$I$2000,台帳!$A$2:$A$2000,$A10,台帳!$D$2:$D$2000,"業者") -> 0 | Q10: =SUM(C10:N10) -> 0 | R10: =R9+C10 -> 0 | S10: =S9+D10 -> 7 | T10: =T9+E10 -> 0 | U10: =U9+F10 -> 0 | V10: =V9+G10 -> 0 | W10: =W9+H10 -> 0 | X10: =X9+I10 -> 0 | Y10: =Y9+J10 -> 0 | ... AF10: =AF9+Q10 -> 7 | AG10: =IFERROR(INDEX(台帳!$H$2:$H$2000,MATCH($A10,台帳!$A$2:$A$2000,0)),"")
A11: 46138 | B11: =CHOOSE(WEEKDAY(A11),"日","月","火","水","木","金","土") -> 日 | C11: =SUMIFS(台帳!$I$2:$I$2000,台帳!$A$2:$A$2000,$A11,台帳!$E$2:$E$2000,C$4) -> 0 | D11: =SUMIFS(台帳!$I$2:$I$2000,台帳!$A$2:$A$2000,$A11,台帳!$E$2:$E$2000,D$4) -> 0 | E11: =SUMIFS(台帳!$I$2:$I$2000,台帳!$A$2:$A$2000,$A11,台帳!$E$2:$E$2000,E$4) -> 0 | F11: =SUMIFS(台帳!$I$2:$I$2000,台帳!$A$2:$A$2000,$A11,台帳!$E$2:$E$2000,F$4) -> 0 | G11: =SUMIFS(台帳!$I$2:$I$2000,台帳!$A$2:$A$2000,$A11,台帳!$E$2:$E$2000,G$4) -> 0 | H11: =SUMIFS(台帳!$I$2:$I$2000,台帳!$A$2:$A$2000,$A11,台帳!$E$2:$E$2000,H$4) -> 0 | I11: =SUMIFS(台帳!$I$2:$I$2000,台帳!$A$2:$A$2000,$A11,台帳!$E$2:$E$2000,I$4) -> 0 | J11: =SUMIFS(台帳!$I$2:$I$2000,台帳!$A$2:$A$2000,$A11,台帳!$E$2:$E$2000,J$4) -> 0 | ... N11: =SUMIFS(台帳!$I$2:$I$2000,台帳!$A$2:$A$2000,$A11,台帳!$E$2:$E$2000,N$4) -> 0 | O11: =SUMIFS(台帳!$I$2:$I$2000,台帳!$A$2:$A$2000,$A11,台帳!$D$2:$D$2000,"自社") -> 0 | P11: =SUMIFS(台帳!$I$2:$I$2000,台帳!$A$2:$A$2000,$A11,台帳!$D$2:$D$2000,"業者") -> 0 | Q11: =SUM(C11:N11) -> 0 | R11: =R10+C11 -> 0 | S11: =S10+D11 -> 7 | T11: =T10+E11 -> 0 | U11: =U10+F11 -> 0 | V11: =V10+G11 -> 0 | W11: =W10+H11 -> 0 | X11: =X10+I11 -> 0 | Y11: =Y10+J11 -> 0 | ... AF11: =AF10+Q11 -> 7 | AG11: =IFERROR(INDEX(台帳!$H$2:$H$2000,MATCH($A11,台帳!$A$2:$A$2000,0)),"")
A12: 46139 | B12: =CHOOSE(WEEKDAY(A12),"日","月","火","水","木","金","土") -> 月 | C12: =SUMIFS(台帳!$I$2:$I$2000,台帳!$A$2:$A$2000,$A12,台帳!$E$2:$E$2000,C$4) -> 0 | D12: =SUMIFS(台帳!$I$2:$I$2000,台帳!$A$2:$A$2000,$A12,台帳!$E$2:$E$2000,D$4) -> 0 | E12: =SUMIFS(台帳!$I$2:$I$2000,台帳!$A$2:$A$2000,$A12,台帳!$E$2:$E$2000,E$4) -> 0 | F12: =SUMIFS(台帳!$I$2:$I$2000,台帳!$A$2:$A$2000,$A12,台帳!$E$2:$E$2000,F$4) -> 0 | G12: =SUMIFS(台帳!$I$2:$I$2000,台帳!$A$2:$A$2000,$A12,台帳!$E$2:$E$2000,G$4) -> 0 | H12: =SUMIFS(台帳!$I$2:$I$2000,台帳!$A$2:$A$2000,$A12,台帳!$E$2:$E$2000,H$4) -> 0 | I12: =SUMIFS(台帳!$I$2:$I$2000,台帳!$A$2:$A$2000,$A12,台帳!$E$2:$E$2000,I$4) -> 0 | J12: =SUMIFS(台帳!$I$2:$I$2000,台帳!$A$2:$A$2000,$A12,台帳!$E$2:$E$2000,J$4) -> 0 | ... N12: =SUMIFS(台帳!$I$2:$I$2000,台帳!$A$2:$A$2000,$A12,台帳!$E$2:$E$2000,N$4) -> 0 | O12: =SUMIFS(台帳!$I$2:$I$2000,台帳!$A$2:$A$2000,$A12,台帳!$D$2:$D$2000,"自社") -> 0 | P12: =SUMIFS(台帳!$I$2:$I$2000,台帳!$A$2:$A$2000,$A12,台帳!$D$2:$D$2000,"業者") -> 0 | Q12: =SUM(C12:N12) -> 0 | R12: =R11+C12 -> 0 | S12: =S11+D12 -> 7 | T12: =T11+E12 -> 0 | U12: =U11+F12 -> 0 | V12: =V11+G12 -> 0 | W12: =W11+H12 -> 0 | X12: =X11+I12 -> 0 | Y12: =Y11+J12 -> 0 | ... AF12: =AF11+Q12 -> 7 | AG12: =IFERROR(INDEX(台帳!$H$2:$H$2000,MATCH($A12,台帳!$A$2:$A$2000,0)),"")
A13: 46140 | B13: =CHOOSE(WEEKDAY(A13),"日","月","火","水","木","金","土") -> 火 | C13: =SUMIFS(台帳!$I$2:$I$2000,台帳!$A$2:$A$2000,$A13,台帳!$E$2:$E$2000,C$4) -> 0 | D13: =SUMIFS(台帳!$I$2:$I$2000,台帳!$A$2:$A$2000,$A13,台帳!$E$2:$E$2000,D$4) -> 0 | E13: =SUMIFS(台帳!$I$2:$I$2000,台帳!$A$2:$A$2000,$A13,台帳!$E$2:$E$2000,E$4) -> 0 | F13: =SUMIFS(台帳!$I$2:$I$2000,台帳!$A$2:$A$2000,$A13,台帳!$E$2:$E$2000,F$4) -> 0 | G13: =SUMIFS(台帳!$I$2:$I$2000,台帳!$A$2:$A$2000,$A13,台帳!$E$2:$E$2000,G$4) -> 0 | H13: =SUMIFS(台帳!$I$2:$I$2000,台帳!$A$2:$A$2000,$A13,台帳!$E$2:$E$2000,H$4) -> 0 | I13: =SUMIFS(台帳!$I$2:$I$2000,台帳!$A$2:$A$2000,$A13,台帳!$E$2:$E$2000,I$4) -> 0 | J13: =SUMIFS(台帳!$I$2:$I$2000,台帳!$A$2:$A$2000,$A13,台帳!$E$2:$E$2000,J$4) -> 0 | ... N13: =SUMIFS(台帳!$I$2:$I$2000,台帳!$A$2:$A$2000,$A13,台帳!$E$2:$E$2000,N$4) -> 0 | O13: =SUMIFS(台帳!$I$2:$I$2000,台帳!$A$2:$A$2000,$A13,台帳!$D$2:$D$2000,"自社") -> 0 | P13: =SUMIFS(台帳!$I$2:$I$2000,台帳!$A$2:$A$2000,$A13,台帳!$D$2:$D$2000,"業者") -> 0 | Q13: =SUM(C13:N13) -> 0 | R13: =R12+C13 -> 0 | S13: =S12+D13 -> 7 | T13: =T12+E13 -> 0 | U13: =U12+F13 -> 0 | V13: =V12+G13 -> 0 | W13: =W12+H13 -> 0 | X13: =X12+I13 -> 0 | Y13: =Y12+J13 -> 0 | ... AF13: =AF12+Q13 -> 7 | AG13: =IFERROR(INDEX(台帳!$H$2:$H$2000,MATCH($A13,台帳!$A$2:$A$2000,0)),"")
A14: 46141 | B14: =CHOOSE(WEEKDAY(A14),"日","月","火","水","木","金","土") -> 水 | C14: =SUMIFS(台帳!$I$2:$I$2000,台帳!$A$2:$A$2000,$A14,台帳!$E$2:$E$2000,C$4) -> 0 | D14: =SUMIFS(台帳!$I$2:$I$2000,台帳!$A$2:$A$2000,$A14,台帳!$E$2:$E$2000,D$4) -> 0 | E14: =SUMIFS(台帳!$I$2:$I$2000,台帳!$A$2:$A$2000,$A14,台帳!$E$2:$E$2000,E$4) -> 0 | F14: =SUMIFS(台帳!$I$2:$I$2000,台帳!$A$2:$A$2000,$A14,台帳!$E$2:$E$2000,F$4) -> 0 | G14: =SUMIFS(台帳!$I$2:$I$2000,台帳!$A$2:$A$2000,$A14,台帳!$E$2:$E$2000,G$4) -> 0 | H14: =SUMIFS(台帳!$I$2:$I$2000,台帳!$A$2:$A$2000,$A14,台帳!$E$2:$E$2000,H$4) -> 0 | I14: =SUMIFS(台帳!$I$2:$I$2000,台帳!$A$2:$A$2000,$A14,台帳!$E$2:$E$2000,I$4) -> 0 | J14: =SUMIFS(台帳!$I$2:$I$2000,台帳!$A$2:$A$2000,$A14,台帳!$E$2:$E$2000,J$4) -> 0 | ... N14: =SUMIFS(台帳!$I$2:$I$2000,台帳!$A$2:$A$2000,$A14,台帳!$E$2:$E$2000,N$4) -> 0 | O14: =SUMIFS(台帳!$I$2:$I$2000,台帳!$A$2:$A$2000,$A14,台帳!$D$2:$D$2000,"自社") -> 0 | P14: =SUMIFS(台帳!$I$2:$I$2000,台帳!$A$2:$A$2000,$A14,台帳!$D$2:$D$2000,"業者") -> 0 | Q14: =SUM(C14:N14) -> 0 | R14: =R13+C14 -> 0 | S14: =S13+D14 -> 7 | T14: =T13+E14 -> 0 | U14: =U13+F14 -> 0 | V14: =V13+G14 -> 0 | W14: =W13+H14 -> 0 | X14: =X13+I14 -> 0 | Y14: =Y13+J14 -> 0 | ... AF14: =AF13+Q14 -> 7 | AG14: =IFERROR(INDEX(台帳!$H$2:$H$2000,MATCH($A14,台帳!$A$2:$A$2000,0)),"")
A15: 46142 | B15: =CHOOSE(WEEKDAY(A15),"日","月","火","水","木","金","土") -> 木 | C15: =SUMIFS(台帳!$I$2:$I$2000,台帳!$A$2:$A$2000,$A15,台帳!$E$2:$E$2000,C$4) -> 0 | D15: =SUMIFS(台帳!$I$2:$I$2000,台帳!$A$2:$A$2000,$A15,台帳!$E$2:$E$2000,D$4) -> 0 | E15: =SUMIFS(台帳!$I$2:$I$2000,台帳!$A$2:$A$2000,$A15,台帳!$E$2:$E$2000,E$4) -> 0 | F15: =SUMIFS(台帳!$I$2:$I$2000,台帳!$A$2:$A$2000,$A15,台帳!$E$2:$E$2000,F$4) -> 0 | G15: =SUMIFS(台帳!$I$2:$I$2000,台帳!$A$2:$A$2000,$A15,台帳!$E$2:$E$2000,G$4) -> 0 | H15: =SUMIFS(台帳!$I$2:$I$2000,台帳!$A$2:$A$2000,$A15,台帳!$E$2:$E$2000,H$4) -> 0 | I15: =SUMIFS(台帳!$I$2:$I$2000,台帳!$A$2:$A$2000,$A15,台帳!$E$2:$E$2000,I$4) -> 0 | J15: =SUMIFS(台帳!$I$2:$I$2000,台帳!$A$2:$A$2000,$A15,台帳!$E$2:$E$2000,J$4) -> 0 | ... N15: =SUMIFS(台帳!$I$2:$I$2000,台帳!$A$2:$A$2000,$A15,台帳!$E$2:$E$2000,N$4) -> 0 | O15: =SUMIFS(台帳!$I$2:$I$2000,台帳!$A$2:$A$2000,$A15,台帳!$D$2:$D$2000,"自社") -> 0 | P15: =SUMIFS(台帳!$I$2:$I$2000,台帳!$A$2:$A$2000,$A15,台帳!$D$2:$D$2000,"業者") -> 0 | Q15: =SUM(C15:N15) -> 0 | R15: =R14+C15 -> 0 | S15: =S14+D15 -> 7 | T15: =T14+E15 -> 0 | U15: =U14+F15 -> 0 | V15: =V14+G15 -> 0 | W15: =W14+H15 -> 0 | X15: =X14+I15 -> 0 | Y15: =Y14+J15 -> 0 | ... AF15: =AF14+Q15 -> 7 | AG15: =IFERROR(INDEX(台帳!$H$2:$H$2000,MATCH($A15,台帳!$A$2:$A$2000,0)),"")
A16: 46143 | B16: =CHOOSE(WEEKDAY(A16),"日","月","火","水","木","金","土") -> 金 | C16: =SUMIFS(台帳!$I$2:$I$2000,台帳!$A$2:$A$2000,$A16,台帳!$E$2:$E$2000,C$4) -> 0 | D16: =SUMIFS(台帳!$I$2:$I$2000,台帳!$A$2:$A$2000,$A16,台帳!$E$2:$E$2000,D$4) -> 0 | E16: =SUMIFS(台帳!$I$2:$I$2000,台帳!$A$2:$A$2000,$A16,台帳!$E$2:$E$2000,E$4) -> 0 | F16: =SUMIFS(台帳!$I$2:$I$2000,台帳!$A$2:$A$2000,$A16,台帳!$E$2:$E$2000,F$4) -> 0 | G16: =SUMIFS(台帳!$I$2:$I$2000,台帳!$A$2:$A$2000,$A16,台帳!$E$2:$E$2000,G$4) -> 0 | H16: =SUMIFS(台帳!$I$2:$I$2000,台帳!$A$2:$A$2000,$A16,台帳!$E$2:$E$2000,H$4) -> 0 | I16: =SUMIFS(台帳!$I$2:$I$2000,台帳!$A$2:$A$2000,$A16,台帳!$E$2:$E$2000,I$4) -> 0 | J16: =SUMIFS(台帳!$I$2:$I$2000,台帳!$A$2:$A$2000,$A16,台帳!$E$2:$E$2000,J$4) -> 0 | ... N16: =SUMIFS(台帳!$I$2:$I$2000,台帳!$A$2:$A$2000,$A16,台帳!$E$2:$E$2000,N$4) -> 0 | O16: =SUMIFS(台帳!$I$2:$I$2000,台帳!$A$2:$A$2000,$A16,台帳!$D$2:$D$2000,"自社") -> 0 | P16: =SUMIFS(台帳!$I$2:$I$2000,台帳!$A$2:$A$2000,$A16,台帳!$D$2:$D$2000,"業者") -> 0 | Q16: =SUM(C16:N16) -> 0 | R16: =R15+C16 -> 0 | S16: =S15+D16 -> 7 | T16: =T15+E16 -> 0 | U16: =U15+F16 -> 0 | V16: =V15+G16 -> 0 | W16: =W15+H16 -> 0 | X16: =X15+I16 -> 0 | Y16: =Y15+J16 -> 0 | ... AF16: =AF15+Q16 -> 7 | AG16: =IFERROR(INDEX(台帳!$H$2:$H$2000,MATCH($A16,台帳!$A$2:$A$2000,0)),"")
A17: 46144 | B17: =CHOOSE(WEEKDAY(A17),"日","月","火","水","木","金","土") -> 土 | C17: =SUMIFS(台帳!$I$2:$I$2000,台帳!$A$2:$A$2000,$A17,台帳!$E$2:$E$2000,C$4) -> 0 | D17: =SUMIFS(台帳!$I$2:$I$2000,台帳!$A$2:$A$2000,$A17,台帳!$E$2:$E$2000,D$4) -> 0 | E17: =SUMIFS(台帳!$I$2:$I$2000,台帳!$A$2:$A$2000,$A17,台帳!$E$2:$E$2000,E$4) -> 0 | F17: =SUMIFS(台帳!$I$2:$I$2000,台帳!$A$2:$A$2000,$A17,台帳!$E$2:$E$2000,F$4) -> 0 | G17: =SUMIFS(台帳!$I$2:$I$2000,台帳!$A$2:$A$2000,$A17,台帳!$E$2:$E$2000,G$4) -> 0 | H17: =SUMIFS(台帳!$I$2:$I$2000,台帳!$A$2:$A$2000,$A17,台帳!$E$2:$E$2000,H$4) -> 0 | I17: =SUMIFS(台帳!$I$2:$I$2000,台帳!$A$2:$A$2000,$A17,台帳!$E$2:$E$2000,I$4) -> 0 | J17: =SUMIFS(台帳!$I$2:$I$2000,台帳!$A$2:$A$2000,$A17,台帳!$E$2:$E$2000,J$4) -> 0 | ... N17: =SUMIFS(台帳!$I$2:$I$2000,台帳!$A$2:$A$2000,$A17,台帳!$E$2:$E$2000,N$4) -> 0 | O17: =SUMIFS(台帳!$I$2:$I$2000,台帳!$A$2:$A$2000,$A17,台帳!$D$2:$D$2000,"自社") -> 0 | P17: =SUMIFS(台帳!$I$2:$I$2000,台帳!$A$2:$A$2000,$A17,台帳!$D$2:$D$2000,"業者") -> 0 | Q17: =SUM(C17:N17) -> 0 | R17: =R16+C17 -> 0 | S17: =S16+D17 -> 7 | T17: =T16+E17 -> 0 | U17: =U16+F17 -> 0 | V17: =V16+G17 -> 0 | W17: =W16+H17 -> 0 | X17: =X16+I17 -> 0 | Y17: =Y16+J17 -> 0 | ... AF17: =AF16+Q17 -> 7 | AG17: =IFERROR(INDEX(台帳!$H$2:$H$2000,MATCH($A17,台帳!$A$2:$A$2000,0)),"")
... A140: 46267 | B140: =CHOOSE(WEEKDAY(A140),"日","月","火","水","木","金","土") -> 水 | C140: =SUMIFS(台帳!$I$2:$I$2000,台帳!$A$2:$A$2000,$A140,台帳!$E$2:$E$2000,C$4) -> 0 | D140: =SUMIFS(台帳!$I$2:$I$2000,台帳!$A$2:$A$2000,$A140,台帳!$E$2:$E$2000,D$4) -> 0 | E140: =SUMIFS(台帳!$I$2:$I$2000,台帳!$A$2:$A$2000,$A140,台帳!$E$2:$E$2000,E$4) -> 0 | F140: =SUMIFS(台帳!$I$2:$I$2000,台帳!$A$2:$A$2000,$A140,台帳!$E$2:$E$2000,F$4) -> 0 | G140: =SUMIFS(台帳!$I$2:$I$2000,台帳!$A$2:$A$2000,$A140,台帳!$E$2:$E$2000,G$4) -> 0 | H140: =SUMIFS(台帳!$I$2:$I$2000,台帳!$A$2:$A$2000,$A140,台帳!$E$2:$E$2000,H$4) -> 0 | I140: =SUMIFS(台帳!$I$2:$I$2000,台帳!$A$2:$A$2000,$A140,台帳!$E$2:$E$2000,I$4) -> 0 | J140: =SUMIFS(台帳!$I$2:$I$2000,台帳!$A$2:$A$2000,$A140,台帳!$E$2:$E$2000,J$4) -> 0 | ... N140: =SUMIFS(台帳!$I$2:$I$2000,台帳!$A$2:$A$2000,$A140,台帳!$E$2:$E$2000,N$4) -> 0 | O140: =SUMIFS(台帳!$I$2:$I$2000,台帳!$A$2:$A$2000,$A140,台帳!$D$2:$D$2000,"自社") -> 3 | P140: =SUMIFS(台帳!$I$2:$I$2000,台帳!$A$2:$A$2000,$A140,台帳!$D$2:$D$2000,"業者") -> 0 | Q140: =SUM(C140:N140) -> 3 | R140: =R139+C140 -> 0 | S140: =S139+D140 -> 7 | T140: =T139+E140 -> 6 | U140: =U139+F140 -> 30 | V140: =V139+G140 -> 51 | W140: =W139+H140 -> 87 | X140: =X139+I140 -> 22 | Y140: =Y139+J140 -> 28 | ... AF140: =AF139+Q140 -> 276 | AG140: =IFERROR(INDEX(台帳!$H$2:$H$2000,MATCH($A140,台帳!$A$2:$A$2000,0)),"") -> 外構土間整地掘削（2tダンプ追加）
A141: 合計 | C141: =SUM(C5:C140) -> 0 | D141: =SUM(D5:D140) -> 7 | E141: =SUM(E5:E140) -> 6 | F141: =SUM(F5:F140) -> 30 | G141: =SUM(G5:G140) -> 51 | H141: =SUM(H5:H140) -> 87 | I141: =SUM(I5:I140) -> 22 | J141: =SUM(J5:J140) -> 28 | ... Q141: =SUM(Q5:Q140) -> 276

Sheet 工種別日別
A1: 工種別 日別人工マトリクス
A2: 行＝日付、列＝工種（工程の順）。台帳から自動集計。
C3: 準備・仮設工事 | D3: 準備・仮設工事 | E3: 土工事 | F3: 土工事 | G3: 擁壁工事 | H3: 地盤改良工事 | I3: 基礎工事 | J3: 基礎工事 | K3: 基礎工事 | L3: 基礎工事 | M3: 基礎工事 | N3: 基礎工事 | O3: 基礎工事 | P3: 木工事 | Q3: 木工事 | R3: 木工事 | S3: 木工事 | T3: 木工事 | U3: 木工事 | V3: 木工事 | W3: 木工事 | X3: 木工事 | Y3: 屋根・外壁工事 | Z3: 屋根・外壁工事 | AA3: 屋根・外壁工事 | AB3: 屋根・外壁工事 | AC3: 屋根・外壁工事 | AD3: 内装仕上げ工事 | AE3: 内装仕上げ工事 | AF3: 内装仕上げ工事 | AG3: 電気設備工事 | AH3: 電気設備工事 | AI3: 給排水設備工事 | AJ3: 給排水設備工事 | AK3: 給排水設備工事 | AL3: 給排水設備工事 | AM3: 外構工事 | AN3: 外構工事 | AO3: その他 | AP3: その他 | AQ3: その他
A4: 日付 | B4: 曜日 | C4: 仮設工事 | D4: 仮設トイレ | E4: 敷地整地 | F4: 残土運搬 | G4: 擁壁基礎整地 | H4: 地盤改良 | I4: 基礎掘削 | J4: 基礎型枠 | K4: 鉄筋工事 | L4: 基礎コンクリート打設 | M4: 左官工事 | N4: ポンプ工事 | O4: 基礎型枠解体・片付け | P4: 土台・床組 | Q4: 上棟 | R4: 軸組・下地 | S4: 外壁下地 | T4: サッシ取付 | U4: 断熱工事 | V4: 天井下地 | W4: 内装下地（PB） | X4: 造作（框・幅木） | Y4: 屋根工事 | Z4: 外壁防水シート | AA4: 外壁サイディング | AB4: コーキング | AC4: 足場 | AD4: クロス工事 | AE4: 床仕上げ（フローリング） | AF4: タイル工事 | AG4: 電気配線 | AH4: 電気器具取付 | AI4: 設備配管 | AJ4: ユニットバス設置 | AK4: 給排水器具取付 | AL4: ガス工事 | AM4: 外構整地・掘削 | AN4: ポーチ・土間 | AO4: 現場管理・清掃 | AP4: 検査 | AQ4: 休工 | AR4: 合計
A5: 46132 | B5: =CHOOSE(WEEKDAY(A5),"日","月","火","水","木","金","土") -> 月 | C5: =SUMIFS(台帳!$I$2:$I$2000,台帳!$A$2:$A$2000,$A5,台帳!$F$2:$F$2000,C$4) -> 0 | D5: =SUMIFS(台帳!$I$2:$I$2000,台帳!$A$2:$A$2000,$A5,台帳!$F$2:$F$2000,D$4) -> 0 | E5: =SUMIFS(台帳!$I$2:$I$2000,台帳!$A$2:$A$2000,$A5,台帳!$F$2:$F$2000,E$4) -> 2 | F5: =SUMIFS(台帳!$I$2:$I$2000,台帳!$A$2:$A$2000,$A5,台帳!$F$2:$F$2000,F$4) -> 0 | G5: =SUMIFS(台帳!$I$2:$I$2000,台帳!$A$2:$A$2000,$A5,台帳!$F$2:$F$2000,G$4) -> 0 | H5: =SUMIFS(台帳!$I$2:$I$2000,台帳!$A$2:$A$2000,$A5,台帳!$F$2:$F$2000,H$4) -> 0 | I5: =SUMIFS(台帳!$I$2:$I$2000,台帳!$A$2:$A$2000,$A5,台帳!$F$2:$F$2000,I$4) -> 0 | J5: =SUMIFS(台帳!$I$2:$I$2000,台帳!$A$2:$A$2000,$A5,台帳!$F$2:$F$2000,J$4) -> 0 | ... AQ5: =SUMIFS(台帳!$I$2:$I$2000,台帳!$A$2:$A$2000,$A5,台帳!$F$2:$F$2000,AQ$4) -> 0 | AR5: =SUM(C5:AQ5) -> 2
A6: 46133 | B6: =CHOOSE(WEEKDAY(A6),"日","月","火","水","木","金","土") -> 火 | C6: =SUMIFS(台帳!$I$2:$I$2000,台帳!$A$2:$A$2000,$A6,台帳!$F$2:$F$2000,C$4) -> 0 | D6: =SUMIFS(台帳!$I$2:$I$2000,台帳!$A$2:$A$2000,$A6,台帳!$F$2:$F$2000,D$4) -> 0 | E6: =SUMIFS(台帳!$I$2:$I$2000,台帳!$A$2:$A$2000,$A6,台帳!$F$2:$F$2000,E$4) -> 2 | F6: =SUMIFS(台帳!$I$2:$I$2000,台帳!$A$2:$A$2000,$A6,台帳!$F$2:$F$2000,F$4) -> 0 | G6: =SUMIFS(台帳!$I$2:$I$2000,台帳!$A$2:$A$2000,$A6,台帳!$F$2:$F$2000,G$4) -> 0 | H6: =SUMIFS(台帳!$I$2:$I$2000,台帳!$A$2:$A$2000,$A6,台帳!$F$2:$F$2000,H$4) -> 0 | I6: =SUMIFS(台帳!$I$2:$I$2000,台帳!$A$2:$A$2000,$A6,台帳!$F$2:$F$2000,I$4) -> 0 | J6: =SUMIFS(台帳!$I$2:$I$2000,台帳!$A$2:$A$2000,$A6,台帳!$F$2:$F$2000,J$4) -> 0 | ... AQ6: =SUMIFS(台帳!$I$2:$I$2000,台帳!$A$2:$A$2000,$A6,台帳!$F$2:$F$2000,AQ$4) -> 0 | AR6: =SUM(C6:AQ6) -> 2
A7: 46134 | B7: =CHOOSE(WEEKDAY(A7),"日","月","火","水","木","金","土") -> 水 | C7: =SUMIFS(台帳!$I$2:$I$2000,台帳!$A$2:$A$2000,$A7,台帳!$F$2:$F$2000,C$4) -> 0 | D7: =SUMIFS(台帳!$I$2:$I$2000,台帳!$A$2:$A$2000,$A7,台帳!$F$2:$F$2000,D$4) -> 0 | E7: =SUMIFS(台帳!$I$2:$I$2000,台帳!$A$2:$A$2000,$A7,台帳!$F$2:$F$2000,E$4) -> 3 | F7: =SUMIFS(台帳!$I$2:$I$2000,台帳!$A$2:$A$2000,$A7,台帳!$F$2:$F$2000,F$4) -> 0 | G7: =SUMIFS(台帳!$I$2:$I$2000,台帳!$A$2:$A$2000,$A7,台帳!$F$2:$F$2000,G$4) -> 0 | H7: =SUMIFS(台帳!$I$2:$I$2000,台帳!$A$2:$A$2000,$A7,台帳!$F$2:$F$2000,H$4) -> 0 | I7: =SUMIFS(台帳!$I$2:$I$2000,台帳!$A$2:$A$2000,$A7,台帳!$F$2:$F$2000,I$4) -> 0 | J7: =SUMIFS(台帳!$I$2:$I$2000,台帳!$A$2:$A$2000,$A7,台帳!$F$2:$F$2000,J$4) -> 0 | ... AQ7: =SUMIFS(台帳!$I$2:$I$2000,台帳!$A$2:$A$2000,$A7,台帳!$F$2:$F$2000,AQ$4) -> 0 | AR7: =SUM(C7:AQ7) -> 3
A8: 46135 | B8: =CHOOSE(WEEKDAY(A8),"日","月","火","水","木","金","土") -> 木 | C8: =SUMIFS(台帳!$I$2:$I$2000,台帳!$A$2:$A$2000,$A8,台帳!$F$2:$F$2000,C$4) -> 0 | D8: =SUMIFS(台帳!$I$2:$I$2000,台帳!$A$2:$A$2000,$A8,台帳!$F$2:$F$2000,D$4) -> 0 | E8: =SUMIFS(台帳!$I$2:$I$2000,台帳!$A$2:$A$2000,$A8,台帳!$F$2:$F$2000,E$4) -> 0 | F8: =SUMIFS(台帳!$I$2:$I$2000,台帳!$A$2:$A$2000,$A8,台帳!$F$2:$F$2000,F$4) -> 0 | G8: =SUMIFS(台帳!$I$2:$I$2000,台帳!$A$2:$A$2000,$A8,台帳!$F$2:$F$2000,G$4) -> 0 | H8: =SUMIFS(台帳!$I$2:$I$2000,台帳!$A$2:$A$2000,$A8,台帳!$F$2:$F$2000,H$4) -> 0 | I8: =SUMIFS(台帳!$I$2:$I$2000,台帳!$A$2:$A$2000,$A8,台帳!$F$2:$F$2000,I$4) -> 0 | J8: =SUMIFS(台帳!$I$2:$I$2000,台帳!$A$2:$A$2000,$A8,台帳!$F$2:$F$2000,J$4) -> 0 | ... AQ8: =SUMIFS(台帳!$I$2:$I$2000,台帳!$A$2:$A$2000,$A8,台帳!$F$2:$F$2000,AQ$4) -> 0 | AR8: =SUM(C8:AQ8) -> 0
A9: 46136 | B9: =CHOOSE(WEEKDAY(A9),"日","月","火","水","木","金","土") -> 金 | C9: =SUMIFS(台帳!$I$2:$I$2000,台帳!$A$2:$A$2000,$A9,台帳!$F$2:$F$2000,C$4) -> 0 | D9: =SUMIFS(台帳!$I$2:$I$2000,台帳!$A$2:$A$2000,$A9,台帳!$F$2:$F$2000,D$4) -> 0 | E9: =SUMIFS(台帳!$I$2:$I$2000,台帳!$A$2:$A$2000,$A9,台帳!$F$2:$F$2000,E$4) -> 0 | F9: =SUMIFS(台帳!$I$2:$I$2000,台帳!$A$2:$A$2000,$A9,台帳!$F$2:$F$2000,F$4) -> 0 | G9: =SUMIFS(台帳!$I$2:$I$2000,台帳!$A$2:$A$2000,$A9,台帳!$F$2:$F$2000,G$4) -> 0 | H9: =SUMIFS(台帳!$I$2:$I$2000,台帳!$A$2:$A$2000,$A9,台帳!$F$2:$F$2000,H$4) -> 0 | I9: =SUMIFS(台帳!$I$2:$I$2000,台帳!$A$2:$A$2000,$A9,台帳!$F$2:$F$2000,I$4) -> 0 | J9: =SUMIFS(台帳!$I$2:$I$2000,台帳!$A$2:$A$2000,$A9,台帳!$F$2:$F$2000,J$4) -> 0 | ... AQ9: =SUMIFS(台帳!$I$2:$I$2000,台帳!$A$2:$A$2000,$A9,台帳!$F$2:$F$2000,AQ$4) -> 0 | AR9: =SUM(C9:AQ9) -> 0
A10: 46137 | B10: =CHOOSE(WEEKDAY(A10),"日","月","火","水","木","金","土") -> 土 | C10: =SUMIFS(台帳!$I$2:$I$2000,台帳!$A$2:$A$2000,$A10,台帳!$F$2:$F$2000,C$4) -> 0 | D10: =SUMIFS(台帳!$I$2:$I$2000,台帳!$A$2:$A$2000,$A10,台帳!$F$2:$F$2000,D$4) -> 0 | E10: =SUMIFS(台帳!$I$2:$I$2000,台帳!$A$2:$A$2000,$A10,台帳!$F$2:$F$2000,E$4) -> 0 | F10: =SUMIFS(台帳!$I$2:$I$2000,台帳!$A$2:$A$2000,$A10,台帳!$F$2:$F$2000,F$4) -> 0 | G10: =SUMIFS(台帳!$I$2:$I$2000,台帳!$A$2:$A$2000,$A10,台帳!$F$2:$F$2000,G$4) -> 0 | H10: =SUMIFS(台帳!$I$2:$I$2000,台帳!$A$2:$A$2000,$A10,台帳!$F$2:$F$2000,H$4) -> 0 | I10: =SUMIFS(台帳!$I$2:$I$2000,台帳!$A$2:$A$2000,$A10,台帳!$F$2:$F$2000,I$4) -> 0 | J10: =SUMIFS(台帳!$I$2:$I$2000,台帳!$A$2:$A$2000,$A10,台帳!$F$2:$F$2000,J$4) -> 0 | ... AQ10: =SUMIFS(台帳!$I$2:$I$2000,台帳!$A$2:$A$2000,$A10,台帳!$F$2:$F$2000,AQ$4) -> 0 | AR10: =SUM(C10:AQ10) -> 0
A11: 46138 | B11: =CHOOSE(WEEKDAY(A11),"日","月","火","水","木","金","土") -> 日 | C11: =SUMIFS(台帳!$I$2:$I$2000,台帳!$A$2:$A$2000,$A11,台帳!$F$2:$F$2000,C$4) -> 0 | D11: =SUMIFS(台帳!$I$2:$I$2000,台帳!$A$2:$A$2000,$A11,台帳!$F$2:$F$2000,D$4) -> 0 | E11: =SUMIFS(台帳!$I$2:$I$2000,台帳!$A$2:$A$2000,$A11,台帳!$F$2:$F$2000,E$4) -> 0 | F11: =SUMIFS(台帳!$I$2:$I$2000,台帳!$A$2:$A$2000,$A11,台帳!$F$2:$F$2000,F$4) -> 0 | G11: =SUMIFS(台帳!$I$2:$I$2000,台帳!$A$2:$A$2000,$A11,台帳!$F$2:$F$2000,G$4) -> 0 | H11: =SUMIFS(台帳!$I$2:$I$2000,台帳!$A$2:$A$2000,$A11,台帳!$F$2:$F$2000,H$4) -> 0 | I11: =SUMIFS(台帳!$I$2:$I$2000,台帳!$A$2:$A$2000,$A11,台帳!$F$2:$F$2000,I$4) -> 0 | J11: =SUMIFS(台帳!$I$2:$I$2000,台帳!$A$2:$A$2000,$A11,台帳!$F$2:$F$2000,J$4) -> 0 | ... AQ11: =SUMIFS(台帳!$I$2:$I$2000,台帳!$A$2:$A$2000,$A11,台帳!$F$2:$F$2000,AQ$4) -> 0 | AR11: =SUM(C11:AQ11) -> 0
A12: 46139 | B12: =CHOOSE(WEEKDAY(A12),"日","月","火","水","木","金","土") -> 月 | C12: =SUMIFS(台帳!$I$2:$I$2000,台帳!$A$2:$A$2000,$A12,台帳!$F$2:$F$2000,C$4) -> 0 | D12: =SUMIFS(台帳!$I$2:$I$2000,台帳!$A$2:$A$2000,$A12,台帳!$F$2:$F$2000,D$4) -> 0 | E12: =SUMIFS(台帳!$I$2:$I$2000,台帳!$A$2:$A$2000,$A12,台帳!$F$2:$F$2000,E$4) -> 0 | F12: =SUMIFS(台帳!$I$2:$I$2000,台帳!$A$2:$A$2000,$A12,台帳!$F$2:$F$2000,F$4) -> 0 | G12: =SUMIFS(台帳!$I$2:$I$2000,台帳!$A$2:$A$2000,$A12,台帳!$F$2:$F$2000,G$4) -> 0 | H12: =SUMIFS(台帳!$I$2:$I$2000,台帳!$A$2:$A$2000,$A12,台帳!$F$2:$F$2000,H$4) -> 0 | I12: =SUMIFS(台帳!$I$2:$I$2000,台帳!$A$2:$A$2000,$A12,台帳!$F$2:$F$2000,I$4) -> 0 | J12: =SUMIFS(台帳!$I$2:$I$2000,台帳!$A$2:$A$2000,$A12,台帳!$F$2:$F$2000,J$4) -> 0 | ... AQ12: =SUMIFS(台帳!$I$2:$I$2000,台帳!$A$2:$A$2000,$A12,台帳!$F$2:$F$2000,AQ$4) -> 0 | AR12: =SUM(C12:AQ12) -> 0
A13: 46140 | B13: =CHOOSE(WEEKDAY(A13),"日","月","火","水","木","金","土") -> 火 | C13: =SUMIFS(台帳!$I$2:$I$2000,台帳!$A$2:$A$2000,$A13,台帳!$F$2:$F$2000,C$4) -> 0 | D13: =SUMIFS(台帳!$I$2:$I$2000,台帳!$A$2:$A$2000,$A13,台帳!$F$2:$F$2000,D$4) -> 0 | E13: =SUMIFS(台帳!$I$2:$I$2000,台帳!$A$2:$A$2000,$A13,台帳!$F$2:$F$2000,E$4) -> 0 | F13: =SUMIFS(台帳!$I$2:$I$2000,台帳!$A$2:$A$2000,$A13,台帳!$F$2:$F$2000,F$4) -> 0 | G13: =SUMIFS(台帳!$I$2:$I$2000,台帳!$A$2:$A$2000,$A13,台帳!$F$2:$F$2000,G$4) -> 0 | H13: =SUMIFS(台帳!$I$2:$I$2000,台帳!$A$2:$A$2000,$A13,台帳!$F$2:$F$2000,H$4) -> 0 | I13: =SUMIFS(台帳!$I$2:$I$2000,台帳!$A$2:$A$2000,$A13,台帳!$F$2:$F$2000,I$4) -> 0 | J13: =SUMIFS(台帳!$I$2:$I$2000,台帳!$A$2:$A$2000,$A13,台帳!$F$2:$F$2000,J$4) -> 0 | ... AQ13: =SUMIFS(台帳!$I$2:$I$2000,台帳!$A$2:$A$2000,$A13,台帳!$F$2:$F$2000,AQ$4) -> 0 | AR13: =SUM(C13:AQ13) -> 0
A14: 46141 | B14: =CHOOSE(WEEKDAY(A14),"日","月","火","水","木","金","土") -> 水 | C14: =SUMIFS(台帳!$I$2:$I$2000,台帳!$A$2:$A$2000,$A14,台帳!$F$2:$F$2000,C$4) -> 0 | D14: =SUMIFS(台帳!$I$2:$I$2000,台帳!$A$2:$A$2000,$A14,台帳!$F$2:$F$2000,D$4) -> 0 | E14: =SUMIFS(台帳!$I$2:$I$2000,台帳!$A$2:$A$2000,$A14,台帳!$F$2:$F$2000,E$4) -> 0 | F14: =SUMIFS(台帳!$I$2:$I$2000,台帳!$A$2:$A$2000,$A14,台帳!$F$2:$F$2000,F$4) -> 0 | G14: =SUMIFS(台帳!$I$2:$I$2000,台帳!$A$2:$A$2000,$A14,台帳!$F$2:$F$2000,G$4) -> 0 | H14: =SUMIFS(台帳!$I$2:$I$2000,台帳!$A$2:$A$2000,$A14,台帳!$F$2:$F$2000,H$4) -> 0 | I14: =SUMIFS(台帳!$I$2:$I$2000,台帳!$A$2:$A$2000,$A14,台帳!$F$2:$F$2000,I$4) -> 0 | J14: =SUMIFS(台帳!$I$2:$I$2000,台帳!$A$2:$A$2000,$A14,台帳!$F$2:$F$2000,J$4) -> 0 | ... AQ14: =SUMIFS(台帳!$I$2:$I$2000,台帳!$A$2:$A$2000,$A14,台帳!$F$2:$F$2000,AQ$4) -> 0 | AR14: =SUM(C14:AQ14) -> 0
A15: 46142 | B15: =CHOOSE(WEEKDAY(A15),"日","月","火","水","木","金","土") -> 木 | C15: =SUMIFS(台帳!$I$2:$I$2000,台帳!$A$2:$A$2000,$A15,台帳!$F$2:$F$2000,C$4) -> 0 | D15: =SUMIFS(台帳!$I$2:$I$2000,台帳!$A$2:$A$2000,$A15,台帳!$F$2:$F$2000,D$4) -> 0 | E15: =SUMIFS(台帳!$I$2:$I$2000,台帳!$A$2:$A$2000,$A15,台帳!$F$2:$F$2000,E$4) -> 0 | F15: =SUMIFS(台帳!$I$2:$I$2000,台帳!$A$2:$A$2000,$A15,台帳!$F$2:$F$2000,F$4) -> 0 | G15: =SUMIFS(台帳!$I$2:$I$2000,台帳!$A$2:$A$2000,$A15,台帳!$F$2:$F$2000,G$4) -> 0 | H15: =SUMIFS(台帳!$I$2:$I$2000,台帳!$A$2:$A$2000,$A15,台帳!$F$2:$F$2000,H$4) -> 0 | I15: =SUMIFS(台帳!$I$2:$I$2000,台帳!$A$2:$A$2000,$A15,台帳!$F$2:$F$2000,I$4) -> 0 | J15: =SUMIFS(台帳!$I$2:$I$2000,台帳!$A$2:$A$2000,$A15,台帳!$F$2:$F$2000,J$4) -> 0 | ... AQ15: =SUMIFS(台帳!$I$2:$I$2000,台帳!$A$2:$A$2000,$A15,台帳!$F$2:$F$2000,AQ$4) -> 0 | AR15: =SUM(C15:AQ15) -> 0
A16: 46143 | B16: =CHOOSE(WEEKDAY(A16),"日","月","火","水","木","金","土") -> 金 | C16: =SUMIFS(台帳!$I$2:$I$2000,台帳!$A$2:$A$2000,$A16,台帳!$F$2:$F$2000,C$4) -> 0 | D16: =SUMIFS(台帳!$I$2:$I$2000,台帳!$A$2:$A$2000,$A16,台帳!$F$2:$F$2000,D$4) -> 0 | E16: =SUMIFS(台帳!$I$2:$I$2000,台帳!$A$2:$A$2000,$A16,台帳!$F$2:$F$2000,E$4) -> 0 | F16: =SUMIFS(台帳!$I$2:$I$2000,台帳!$A$2:$A$2000,$A16,台帳!$F$2:$F$2000,F$4) -> 0 | G16: =SUMIFS(台帳!$I$2:$I$2000,台帳!$A$2:$A$2000,$A16,台帳!$F$2:$F$2000,G$4) -> 0 | H16: =SUMIFS(台帳!$I$2:$I$2000,台帳!$A$2:$A$2000,$A16,台帳!$F$2:$F$2000,H$4) -> 0 | I16: =SUMIFS(台帳!$I$2:$I$2000,台帳!$A$2:$A$2000,$A16,台帳!$F$2:$F$2000,I$4) -> 0 | J16: =SUMIFS(台帳!$I$2:$I$2000,台帳!$A$2:$A$2000,$A16,台帳!$F$2:$F$2000,J$4) -> 0 | ... AQ16: =SUMIFS(台帳!$I$2:$I$2000,台帳!$A$2:$A$2000,$A16,台帳!$F$2:$F$2000,AQ$4) -> 0 | AR16: =SUM(C16:AQ16) -> 0
... A140: 46267 | B140: =CHOOSE(WEEKDAY(A140),"日","月","火","水","木","金","土") -> 水 | C140: =SUMIFS(台帳!$I$2:$I$2000,台帳!$A$2:$A$2000,$A140,台帳!$F$2:$F$2000,C$4) -> 0 | D140: =SUMIFS(台帳!$I$2:$I$2000,台帳!$A$2:$A$2000,$A140,台帳!$F$2:$F$2000,D$4) -> 0 | E140: =SUMIFS(台帳!$I$2:$I$2000,台帳!$A$2:$A$2000,$A140,台帳!$F$2:$F$2000,E$4) -> 0 | F140: =SUMIFS(台帳!$I$2:$I$2000,台帳!$A$2:$A$2000,$A140,台帳!$F$2:$F$2000,F$4) -> 0 | G140: =SUMIFS(台帳!$I$2:$I$2000,台帳!$A$2:$A$2000,$A140,台帳!$F$2:$F$2000,G$4) -> 0 | H140: =SUMIFS(台帳!$I$2:$I$2000,台帳!$A$2:$A$2000,$A140,台帳!$F$2:$F$2000,H$4) -> 0 | I140: =SUMIFS(台帳!$I$2:$I$2000,台帳!$A$2:$A$2000,$A140,台帳!$F$2:$F$2000,I$4) -> 0 | J140: =SUMIFS(台帳!$I$2:$I$2000,台帳!$A$2:$A$2000,$A140,台帳!$F$2:$F$2000,J$4) -> 0 | ... AQ140: =SUMIFS(台帳!$I$2:$I$2000,台帳!$A$2:$A$2000,$A140,台帳!$F$2:$F$2000,AQ$4) -> 0 | AR140: =SUM(C140:AQ140) -> 3
A141: 合計 | C141: =SUM(C5:C140) -> 0 | D141: =SUM(D5:D140) -> 0 | E141: =SUM(E5:E140) -> 7 | F141: =SUM(F5:F140) -> 0 | G141: =SUM(G5:G140) -> 6 | H141: =SUM(H5:H140) -> 30 | I141: =SUM(I5:I140) -> 12 | J141: =SUM(J5:J140) -> 21 | ... AR141: =SUM(AR5:AR140) -> 276

Sheet 確認事項
A1: 確認事項（元日報から読み取れなかった点・修正した点）
A2: 台帳の「備考」「元記載」列にも同じ内容を残しています。
A4: 区分 | B4: 内容 | C4: 備考・要確認
A5: 名寄せ | B5: 荷川取強／荷川取り／荷川取 剛／仁川取り／二箇取り／理科取り／リカ取り／に取り／湯川取り／三川取り／取り → 「荷川取」 | C5: 作業員マスター確定後に置換
A6: 名寄せ | B6: 当山／東山／當山／当山清／東山清／洞爺清 → 「當山」 | C6: 同上
A7: 名寄せ | B7: 友寄司 → 「友寄」、宮城久一 → 「宮城」 | C7: 同上
A8: 名寄せ | B8: 電気業者／電気工事 → 「電気業者」、外壁工事 → 「外壁サイディング業者」、内装業者 → 「内装業者（クロス）」 | C8: 業者名が分かれば置換
A9: 日付修正 | B9: 「5月19日水曜日」→ 5/20（水） | C9: 5/19（火）の次の日と判断
A10: 日付修正 | B10: 「6月7日火曜日」→ 7/7（火） | C10: 7/6（月）と7/8（水）の間
A11: 日付修正 | B11: 「6月24日木曜日」→ 6/25（木）、「6月25日金曜日」→ 6/26（金） | C11: 6/24は水曜のため順送り
A12: 日付修正 | B12: 「6月26日から28日まで台風」→ 6/27〜28 を休工 | C12: 6/26は作業記録があるため
A13: 日付修正 | B13: 「7月9日木曜日から6月11日土曜日」→ 7/9〜7/11 養生
A14: 人工不明 | B14: 4/20 一輝興業（ダンプ6台）、4/21 当間均（ダンプ1台） | C14: 運搬は人工に含めず台数のみ。人工計上するか要確認
A15: 人工不明 | B15: 7/14 設備配管、7/18 クレーン業者 | C15: 人数の記載なし → 人工空欄
A16: 作業員不明 | B16: 7/28、8/27 は自社作業員の記載なし | C16: 人工空欄（8/27は水道業者のみ）
A17: 作業内容不明 | B17: 7/29・7/30（自社2名）、8/6、8/10、8/13、8/19 | C17: 前後の日から工種を推定して入力（備考に明記）
A18: 解釈 | B18: 4/20「ミニユンボ, 21台」→ 0.2 1台、9/1「本間1ユンボ」→ コンマ1（0.1）ユンボ
A19: 解釈 | B19: 7/3「土間左官 東山、その他1人」→ 當山（自社）1 ＋ 左官業者 1 | C19: その他1人が自社か業者か要確認
A20: 解釈 | B20: 7/16「ゆか値段の張り」7/17「床張り値段の」→ 床下地張り／床張り | C20: 音声入力の誤変換と判断
A21: 解釈 | B21: 7/13「気象型枠材」「1部ビーコン埋め」 | C21: 判読不明のまま備考に記載
A22: 解釈 | B22: 8/1「明日建設株式会社」→ アース建設
A23: 解釈 | B23: 8/17「クロス工事 2人9」→ 2人、8/30「推薦取り付け」→ 水栓取付、8/31「玄関釜」→ 玄関框
A24: 解釈 | B24: 8/17 自社は長嶺邸フェンス工事のため谷邸は休工扱い（人工0） | C24: 長嶺邸側の日報に計上
A25: ルール | B25: 半日・数時間（4/22 友寄、6/16 雨天半日、7/21 當山、7/27 宮城、8/4-5 山里、8/10-11 友寄、8/11 宮城、8/13 荷川取、8/28 宮城）→ 1人工 | C25: 2026/9/2 決定
A26: ルール | B26: 6/24 仮設トイレ設置は掘削作業と兼務のため人工0（記録のみ）
A27: ルール | B27: 別現場（かりゆしファーム・沖縄銀行・長嶺邸）にいた時間は谷邸には計上しない | C27: その現場の日報側で計上
A28: 工種追加 | B28: 8/10以降で 天井下地・屋根工事・クロス工事・床仕上げ・造作・足場・ガス・給排水器具・タイル・外構整地・ポーチ土間・検査 を追加 | C28: 工種は随時追加可

Sheet 印刷01_日別人工
A1: 日別 人工（工程別・自社／業者）
A2: 台帳から自動集計。灰色＝土日。
A4: 日付 | B4: 曜日 | C4: 準備・仮設工事 | D4: 土工事 | E4: 擁壁工事 | F4: 地盤改良工事 | G4: 基礎工事 | H4: 木工事 | I4: 屋根・外壁工事 | J4: 内装仕上げ工事 | K4: 電気設備工事 | L4: 給排水設備工事 | M4: 外構工事 | N4: その他 | O4: 自社 | P4: 業者 | Q4: 合計
A5: =IF(日別集計!A5="","",日別集計!A5) -> 46132 | B5: =IF(日別集計!B5="","",日別集計!B5) -> 月 | C5: =IF(日別集計!C5="","",日別集計!C5) -> 0 | D5: =IF(日別集計!D5="","",日別集計!D5) -> 2 | E5: =IF(日別集計!E5="","",日別集計!E5) -> 0 | F5: =IF(日別集計!F5="","",日別集計!F5) -> 0 | G5: =IF(日別集計!G5="","",日別集計!G5) -> 0 | H5: =IF(日別集計!H5="","",日別集計!H5) -> 0 | ... Q5: =IF(日別集計!Q5="","",日別集計!Q5) -> 2
A6: =IF(日別集計!A6="","",日別集計!A6) -> 46133 | B6: =IF(日別集計!B6="","",日別集計!B6) -> 火 | C6: =IF(日別集計!C6="","",日別集計!C6) -> 0 | D6: =IF(日別集計!D6="","",日別集計!D6) -> 2 | E6: =IF(日別集計!E6="","",日別集計!E6) -> 0 | F6: =IF(日別集計!F6="","",日別集計!F6) -> 0 | G6: =IF(日別集計!G6="","",日別集計!G6) -> 0 | H6: =IF(日別集計!H6="","",日別集計!H6) -> 0 | ... Q6: =IF(日別集計!Q6="","",日別集計!Q6) -> 2
A7: =IF(日別集計!A7="","",日別集計!A7) -> 46134 | B7: =IF(日別集計!B7="","",日別集計!B7) -> 水 | C7: =IF(日別集計!C7="","",日別集計!C7) -> 0 | D7: =IF(日別集計!D7="","",日別集計!D7) -> 3 | E7: =IF(日別集計!E7="","",日別集計!E7) -> 0 | F7: =IF(日別集計!F7="","",日別集計!F7) -> 0 | G7: =IF(日別集計!G7="","",日別集計!G7) -> 0 | H7: =IF(日別集計!H7="","",日別集計!H7) -> 0 | ... Q7: =IF(日別集計!Q7="","",日別集計!Q7) -> 3
A8: =IF(日別集計!A8="","",日別集計!A8) -> 46135 | B8: =IF(日別集計!B8="","",日別集計!B8) -> 木 | C8: =IF(日別集計!C8="","",日別集計!C8) -> 0 | D8: =IF(日別集計!D8="","",日別集計!D8) -> 0 | E8: =IF(日別集計!E8="","",日別集計!E8) -> 0 | F8: =IF(日別集計!F8="","",日別集計!F8) -> 0 | G8: =IF(日別集計!G8="","",日別集計!G8) -> 0 | H8: =IF(日別集計!H8="","",日別集計!H8) -> 0 | ... Q8: =IF(日別集計!Q8="","",日別集計!Q8) -> 0
A9: =IF(日別集計!A9="","",日別集計!A9) -> 46136 | B9: =IF(日別集計!B9="","",日別集計!B9) -> 金 | C9: =IF(日別集計!C9="","",日別集計!C9) -> 0 | D9: =IF(日別集計!D9="","",日別集計!D9) -> 0 | E9: =IF(日別集計!E9="","",日別集計!E9) -> 0 | F9: =IF(日別集計!F9="","",日別集計!F9) -> 0 | G9: =IF(日別集計!G9="","",日別集計!G9) -> 0 | H9: =IF(日別集計!H9="","",日別集計!H9) -> 0 | ... Q9: =IF(日別集計!Q9="","",日別集計!Q9) -> 0
A10: =IF(日別集計!A10="","",日別集計!A10) -> 46137 | B10: =IF(日別集計!B10="","",日別集計!B10) -> 土 | C10: =IF(日別集計!C10="","",日別集計!C10) -> 0 | D10: =IF(日別集計!D10="","",日別集計!D10) -> 0 | E10: =IF(日別集計!E10="","",日別集計!E10) -> 0 | F10: =IF(日別集計!F10="","",日別集計!F10) -> 0 | G10: =IF(日別集計!G10="","",日別集計!G10) -> 0 | H10: =IF(日別集計!H10="","",日別集計!H10) -> 0 | ... Q10: =IF(日別集計!Q10="","",日別集計!Q10) -> 0
A11: =IF(日別集計!A11="","",日別集計!A11) -> 46138 | B11: =IF(日別集計!B11="","",日別集計!B11) -> 日 | C11: =IF(日別集計!C11="","",日別集計!C11) -> 0 | D11: =IF(日別集計!D11="","",日別集計!D11) -> 0 | E11: =IF(日別集計!E11="","",日別集計!E11) -> 0 | F11: =IF(日別集計!F11="","",日別集計!F11) -> 0 | G11: =IF(日別集計!G11="","",日別集計!G11) -> 0 | H11: =IF(日別集計!H11="","",日別集計!H11) -> 0 | ... Q11: =IF(日別集計!Q11="","",日別集計!Q11) -> 0
A12: =IF(日別集計!A12="","",日別集計!A12) -> 46139 | B12: =IF(日別集計!B12="","",日別集計!B12) -> 月 | C12: =IF(日別集計!C12="","",日別集計!C12) -> 0 | D12: =IF(日別集計!D12="","",日別集計!D12) -> 0 | E12: =IF(日別集計!E12="","",日別集計!E12) -> 0 | F12: =IF(日別集計!F12="","",日別集計!F12) -> 0 | G12: =IF(日別集計!G12="","",日別集計!G12) -> 0 | H12: =IF(日別集計!H12="","",日別集計!H12) -> 0 | ... Q12: =IF(日別集計!Q12="","",日別集計!Q12) -> 0
A13: =IF(日別集計!A13="","",日別集計!A13) -> 46140 | B13: =IF(日別集計!B13="","",日別集計!B13) -> 火 | C13: =IF(日別集計!C13="","",日別集計!C13) -> 0 | D13: =IF(日別集計!D13="","",日別集計!D13) -> 0 | E13: =IF(日別集計!E13="","",日別集計!E13) -> 0 | F13: =IF(日別集計!F13="","",日別集計!F13) -> 0 | G13: =IF(日別集計!G13="","",日別集計!G13) -> 0 | H13: =IF(日別集計!H13="","",日別集計!H13) -> 0 | ... Q13: =IF(日別集計!Q13="","",日別集計!Q13) -> 0
A14: =IF(日別集計!A14="","",日別集計!A14) -> 46141 | B14: =IF(日別集計!B14="","",日別集計!B14) -> 水 | C14: =IF(日別集計!C14="","",日別集計!C14) -> 0 | D14: =IF(日別集計!D14="","",日別集計!D14) -> 0 | E14: =IF(日別集計!E14="","",日別集計!E14) -> 0 | F14: =IF(日別集計!F14="","",日別集計!F14) -> 0 | G14: =IF(日別集計!G14="","",日別集計!G14) -> 0 | H14: =IF(日別集計!H14="","",日別集計!H14) -> 0 | ... Q14: =IF(日別集計!Q14="","",日別集計!Q14) -> 0
A15: =IF(日別集計!A15="","",日別集計!A15) -> 46142 | B15: =IF(日別集計!B15="","",日別集計!B15) -> 木 | C15: =IF(日別集計!C15="","",日別集計!C15) -> 0 | D15: =IF(日別集計!D15="","",日別集計!D15) -> 0 | E15: =IF(日別集計!E15="","",日別集計!E15) -> 0 | F15: =IF(日別集計!F15="","",日別集計!F15) -> 0 | G15: =IF(日別集計!G15="","",日別集計!G15) -> 0 | H15: =IF(日別集計!H15="","",日別集計!H15) -> 0 | ... Q15: =IF(日別集計!Q15="","",日別集計!Q15) -> 0
A16: =IF(日別集計!A16="","",日別集計!A16) -> 46143 | B16: =IF(日別集計!B16="","",日別集計!B16) -> 金 | C16: =IF(日別集計!C16="","",日別集計!C16) -> 0 | D16: =IF(日別集計!D16="","",日別集計!D16) -> 0 | E16: =IF(日別集計!E16="","",日別集計!E16) -> 0 | F16: =IF(日別集計!F16="","",日別集計!F16) -> 0 | G16: =IF(日別集計!G16="","",日別集計!G16) -> 0 | H16: =IF(日別集計!H16="","",日別集計!H16) -> 0 | ... Q16: =IF(日別集計!Q16="","",日別集計!Q16) -> 0
... A141: =IF(日別集計!A141="","",日別集計!A141) -> 合計 | B141: =IF(日別集計!B141="","",日別集計!B141) | C141: =IF(日別集計!C141="","",日別集計!C141) -> 0 | D141: =IF(日別集計!D141="","",日別集計!D141) -> 7 | E141: =IF(日別集計!E141="","",日別集計!E141) -> 6 | F141: =IF(日別集計!F141="","",日別集計!F141) -> 30 | G141: =IF(日別集計!G141="","",日別集計!G141) -> 51 | H141: =IF(日別集計!H141="","",日別集計!H141) -> 87 | ... Q141: =IF(日別集計!Q141="","",日別集計!Q141) -> 276

Sheet 印刷02_累計推移
A1: 累計人工の推移（工程別）と当日の作業内容
A2: 各工程の累計人工が日ごとにどう積み上がったか。右端はその日の自社作業内容（先頭行）。
A4: 日付 | B4: 曜日 | C4: 累計 準備・仮設工事 | D4: 累計 土工事 | E4: 累計 擁壁工事 | F4: 累計 地盤改良工事 | G4: 累計 基礎工事 | H4: 累計 木工事 | I4: 累計 屋根・外壁工事 | J4: 累計 内装仕上げ工事 | K4: 累計 電気設備工事 | L4: 累計 給排水設備工事 | M4: 累計 外構工事 | N4: 累計 その他 | O4: 累計 自社 | P4: 累計 業者 | Q4: 累計 合計 | R4: その日の作業内容（自社）
A5: =IF(日別集計!A5="","",日別集計!A5) -> 46132 | B5: =IF(日別集計!B5="","",日別集計!B5) -> 月 | C5: =IF(日別集計!R5="","",日別集計!R5) -> 0 | D5: =IF(日別集計!S5="","",日別集計!S5) -> 2 | E5: =IF(日別集計!T5="","",日別集計!T5) -> 0 | F5: =IF(日別集計!U5="","",日別集計!U5) -> 0 | G5: =IF(日別集計!V5="","",日別集計!V5) -> 0 | H5: =IF(日別集計!W5="","",日別集計!W5) -> 0 | I5: =IF(日別集計!X5="","",日別集計!X5) -> 0 | J5: =IF(日別集計!Y5="","",日別集計!Y5) -> 0 | ... R5: =IF(日別集計!AG5="","",日別集計!AG5) -> 敷地整地
A6: =IF(日別集計!A6="","",日別集計!A6) -> 46133 | B6: =IF(日別集計!B6="","",日別集計!B6) -> 火 | C6: =IF(日別集計!R6="","",日別集計!R6) -> 0 | D6: =IF(日別集計!S6="","",日別集計!S6) -> 4 | E6: =IF(日別集計!T6="","",日別集計!T6) -> 0 | F6: =IF(日別集計!U6="","",日別集計!U6) -> 0 | G6: =IF(日別集計!V6="","",日別集計!V6) -> 0 | H6: =IF(日別集計!W6="","",日別集計!W6) -> 0 | I6: =IF(日別集計!X6="","",日別集計!X6) -> 0 | J6: =IF(日別集計!Y6="","",日別集計!Y6) -> 0 | ... R6: =IF(日別集計!AG6="","",日別集計!AG6) -> 敷地整地
A7: =IF(日別集計!A7="","",日別集計!A7) -> 46134 | B7: =IF(日別集計!B7="","",日別集計!B7) -> 水 | C7: =IF(日別集計!R7="","",日別集計!R7) -> 0 | D7: =IF(日別集計!S7="","",日別集計!S7) -> 7 | E7: =IF(日別集計!T7="","",日別集計!T7) -> 0 | F7: =IF(日別集計!U7="","",日別集計!U7) -> 0 | G7: =IF(日別集計!V7="","",日別集計!V7) -> 0 | H7: =IF(日別集計!W7="","",日別集計!W7) -> 0 | I7: =IF(日別集計!X7="","",日別集計!X7) -> 0 | J7: =IF(日別集計!Y7="","",日別集計!Y7) -> 0 | ... R7: =IF(日別集計!AG7="","",日別集計!AG7) -> 敷地整地
A8: =IF(日別集計!A8="","",日別集計!A8) -> 46135 | B8: =IF(日別集計!B8="","",日別集計!B8) -> 木 | C8: =IF(日別集計!R8="","",日別集計!R8) -> 0 | D8: =IF(日別集計!S8="","",日別集計!S8) -> 7 | E8: =IF(日別集計!T8="","",日別集計!T8) -> 0 | F8: =IF(日別集計!U8="","",日別集計!U8) -> 0 | G8: =IF(日別集計!V8="","",日別集計!V8) -> 0 | H8: =IF(日別集計!W8="","",日別集計!W8) -> 0 | I8: =IF(日別集計!X8="","",日別集計!X8) -> 0 | J8: =IF(日別集計!Y8="","",日別集計!Y8) -> 0 | ... R8: =IF(日別集計!AG8="","",日別集計!AG8)
A9: =IF(日別集計!A9="","",日別集計!A9) -> 46136 | B9: =IF(日別集計!B9="","",日別集計!B9) -> 金 | C9: =IF(日別集計!R9="","",日別集計!R9) -> 0 | D9: =IF(日別集計!S9="","",日別集計!S9) -> 7 | E9: =IF(日別集計!T9="","",日別集計!T9) -> 0 | F9: =IF(日別集計!U9="","",日別集計!U9) -> 0 | G9: =IF(日別集計!V9="","",日別集計!V9) -> 0 | H9: =IF(日別集計!W9="","",日別集計!W9) -> 0 | I9: =IF(日別集計!X9="","",日別集計!X9) -> 0 | J9: =IF(日別集計!Y9="","",日別集計!Y9) -> 0 | ... R9: =IF(日別集計!AG9="","",日別集計!AG9)
A10: =IF(日別集計!A10="","",日別集計!A10) -> 46137 | B10: =IF(日別集計!B10="","",日別集計!B10) -> 土 | C10: =IF(日別集計!R10="","",日別集計!R10) -> 0 | D10: =IF(日別集計!S10="","",日別集計!S10) -> 7 | E10: =IF(日別集計!T10="","",日別集計!T10) -> 0 | F10: =IF(日別集計!U10="","",日別集計!U10) -> 0 | G10: =IF(日別集計!V10="","",日別集計!V10) -> 0 | H10: =IF(日別集計!W10="","",日別集計!W10) -> 0 | I10: =IF(日別集計!X10="","",日別集計!X10) -> 0 | J10: =IF(日別集計!Y10="","",日別集計!Y10) -> 0 | ... R10: =IF(日別集計!AG10="","",日別集計!AG10)
A11: =IF(日別集計!A11="","",日別集計!A11) -> 46138 | B11: =IF(日別集計!B11="","",日別集計!B11) -> 日 | C11: =IF(日別集計!R11="","",日別集計!R11) -> 0 | D11: =IF(日別集計!S11="","",日別集計!S11) -> 7 | E11: =IF(日別集計!T11="","",日別集計!T11) -> 0 | F11: =IF(日別集計!U11="","",日別集計!U11) -> 0 | G11: =IF(日別集計!V11="","",日別集計!V11) -> 0 | H11: =IF(日別集計!W11="","",日別集計!W11) -> 0 | I11: =IF(日別集計!X11="","",日別集計!X11) -> 0 | J11: =IF(日別集計!Y11="","",日別集計!Y11) -> 0 | ... R11: =IF(日別集計!AG11="","",日別集計!AG11)
A12: =IF(日別集計!A12="","",日別集計!A12) -> 46139 | B12: =IF(日別集計!B12="","",日別集計!B12) -> 月 | C12: =IF(日別集計!R12="","",日別集計!R12) -> 0 | D12: =IF(日別集計!S12="","",日別集計!S12) -> 7 | E12: =IF(日別集計!T12="","",日別集計!T12) -> 0 | F12: =IF(日別集計!U12="","",日別集計!U12) -> 0 | G12: =IF(日別集計!V12="","",日別集計!V12) -> 0 | H12: =IF(日別集計!W12="","",日別集計!W12) -> 0 | I12: =IF(日別集計!X12="","",日別集計!X12) -> 0 | J12: =IF(日別集計!Y12="","",日別集計!Y12) -> 0 | ... R12: =IF(日別集計!AG12="","",日別集計!AG12)
A13: =IF(日別集計!A13="","",日別集計!A13) -> 46140 | B13: =IF(日別集計!B13="","",日別集計!B13) -> 火 | C13: =IF(日別集計!R13="","",日別集計!R13) -> 0 | D13: =IF(日別集計!S13="","",日別集計!S13) -> 7 | E13: =IF(日別集計!T13="","",日別集計!T13) -> 0 | F13: =IF(日別集計!U13="","",日別集計!U13) -> 0 | G13: =IF(日別集計!V13="","",日別集計!V13) -> 0 | H13: =IF(日別集計!W13="","",日別集計!W13) -> 0 | I13: =IF(日別集計!X13="","",日別集計!X13) -> 0 | J13: =IF(日別集計!Y13="","",日別集計!Y13) -> 0 | ... R13: =IF(日別集計!AG13="","",日別集計!AG13)
A14: =IF(日別集計!A14="","",日別集計!A14) -> 46141 | B14: =IF(日別集計!B14="","",日別集計!B14) -> 水 | C14: =IF(日別集計!R14="","",日別集計!R14) -> 0 | D14: =IF(日別集計!S14="","",日別集計!S14) -> 7 | E14: =IF(日別集計!T14="","",日別集計!T14) -> 0 | F14: =IF(日別集計!U14="","",日別集計!U14) -> 0 | G14: =IF(日別集計!V14="","",日別集計!V14) -> 0 | H14: =IF(日別集計!W14="","",日別集計!W14) -> 0 | I14: =IF(日別集計!X14="","",日別集計!X14) -> 0 | J14: =IF(日別集計!Y14="","",日別集計!Y14) -> 0 | ... R14: =IF(日別集計!AG14="","",日別集計!AG14)
A15: =IF(日別集計!A15="","",日別集計!A15) -> 46142 | B15: =IF(日別集計!B15="","",日別集計!B15) -> 木 | C15: =IF(日別集計!R15="","",日別集計!R15) -> 0 | D15: =IF(日別集計!S15="","",日別集計!S15) -> 7 | E15: =IF(日別集計!T15="","",日別集計!T15) -> 0 | F15: =IF(日別集計!U15="","",日別集計!U15) -> 0 | G15: =IF(日別集計!V15="","",日別集計!V15) -> 0 | H15: =IF(日別集計!W15="","",日別集計!W15) -> 0 | I15: =IF(日別集計!X15="","",日別集計!X15) -> 0 | J15: =IF(日別集計!Y15="","",日別集計!Y15) -> 0 | ... R15: =IF(日別集計!AG15="","",日別集計!AG15)
A16: =IF(日別集計!A16="","",日別集計!A16) -> 46143 | B16: =IF(日別集計!B16="","",日別集計!B16) -> 金 | C16: =IF(日別集計!R16="","",日別集計!R16) -> 0 | D16: =IF(日別集計!S16="","",日別集計!S16) -> 7 | E16: =IF(日別集計!T16="","",日別集計!T16) -> 0 | F16: =IF(日別集計!U16="","",日別集計!U16) -> 0 | G16: =IF(日別集計!V16="","",日別集計!V16) -> 0 | H16: =IF(日別集計!W16="","",日別集計!W16) -> 0 | I16: =IF(日別集計!X16="","",日別集計!X16) -> 0 | J16: =IF(日別集計!Y16="","",日別集計!Y16) -> 0 | ... R16: =IF(日別集計!AG16="","",日別集計!AG16)
